<?xml version='1.0'?>
<sdf version='1.6'>
  <model name='gtrobot_base'>
    <link name='base_footprint'>
      <pose frame=''>0 0 0 0 -0 0</pose>
      <inertial>
        <pose frame=''>0 0 0.001 0 -0 0</pose>
        <mass>10</mass>
        <inertia>
          <ixx>1.51875</ixx>
          <ixy>0</ixy>
          <ixz>0</ixz>
          <iyy>0.385334</iyy>
          <iyz>0</iyz>
          <izz>1.90408</izz>
        </inertia>
      </inertial>
      <visual name='base_footprint_visual'>
        <pose frame=''>0 0 0 0 -0 0</pose>
        <geometry>
          <box>
            <size>0.001 0.001 0.001</size>
          </box>
        </geometry>
        <material>
          <script>
            <name>Gazebo/White</name>
            <uri>file://media/materials/scripts/gazebo.material</uri>
          </script>
        </material>
      </visual>
      <visual name='base_footprint_fixed_joint_lump__fixed_link_visual_1'>
        <pose frame=''>0 0 0.001 0 -0 0</pose>
        <geometry>
          <box>
            <size>0.68 1.35 0.001</size>
          </box>
        </geometry>
        <material>
          <script>
            <name>Gazebo/White</name>
            <uri>file://media/materials/scripts/gazebo.material</uri>
          </script>
        </material>
      </visual>
      <velocity_decay/>
      <gravity>1</gravity>
      <velocity_decay/>
      <self_collide>0</self_collide>
      <enable_wind>0</enable_wind>
      <kinematic>0</kinematic>
    </link>
    <link name='x_axis_link'>
      <pose frame=''>0 0 0.011 0 -0 0</pose>
      <inertial>
        <pose frame=''>0 0 0 0 -0 0</pose>
        <mass>0.1</mass>
        <inertia>
          <ixx>0.0151883</ixx>
          <ixy>0</ixy>
          <ixz>0</ixz>
          <iyy>0.00385417</iyy>
          <iyz>0</iyz>
          <izz>0.0190408</izz>
        </inertia>
      </inertial>
      <visual name='x_axis_link_visual'>
        <pose frame=''>0 0 0 0 -0 0</pose>
        <geometry>
          <box>
            <size>0.68 1.35 0.01</size>
          </box>
        </geometry>
        <material>
          <script>
            <name>Gazebo/Red</name>
            <uri>file://media/materials/scripts/gazebo.material</uri>
          </script>
        </material>
      </visual>
      <gravity>1</gravity>
      <velocity_decay/>
      <self_collide>0</self_collide>
      <enable_wind>0</enable_wind>
      <kinematic>0</kinematic>
    </link>
    <joint name='x_axis_joint' type='prismatic'>
      <child>x_axis_link</child>
      <parent>base_footprint</parent>
      <axis>
        <xyz>1 0 0</xyz>
        <limit>
          <lower>-5</lower>
          <upper>5</upper>
          <effort>10000</effort>
          <velocity>1</velocity>
        </limit>
        <dynamics>
          <spring_reference>0</spring_reference>
          <spring_stiffness>0</spring_stiffness>
        </dynamics>
        <use_parent_model_frame>1</use_parent_model_frame>
      </axis>
    </joint>
    <link name='y_axis_link'>
      <pose frame=''>0 0 0.021 0 -0 0</pose>
      <inertial>
        <pose frame=''>0 0 0 0 -0 0</pose>
        <mass>0.1</mass>
        <inertia>
          <ixx>0.0151883</ixx>
          <ixy>0</ixy>
          <ixz>0</ixz>
          <iyy>0.00385417</iyy>
          <iyz>0</iyz>
          <izz>0.0190408</izz>
        </inertia>
      </inertial>
      <visual name='y_axis_link_visual'>
        <pose frame=''>0 0 0 0 -0 0</pose>
        <geometry>
          <box>
            <size>0.68 1.35 0.01</size>
          </box>
        </geometry>
        <material>
          <script>
            <name>Gazebo/Green</name>
            <uri>file://media/materials/scripts/gazebo.material</uri>
          </script>
        </material>
      </visual>
      <gravity>1</gravity>
      <velocity_decay/>
      <self_collide>0</self_collide>
      <enable_wind>0</enable_wind>
      <kinematic>0</kinematic>
    </link>
    <joint name='y_axis_joint' type='prismatic'>
      <child>y_axis_link</child>
      <parent>x_axis_link</parent>
      <axis>
        <xyz>0 1 0</xyz>
        <limit>
          <lower>-5</lower>
          <upper>5</upper>
          <effort>10000</effort>
          <velocity>1</velocity>
        </limit>
        <dynamics>
          <spring_reference>0</spring_reference>
          <spring_stiffness>0</spring_stiffness>
        </dynamics>
        <use_parent_model_frame>1</use_parent_model_frame>
      </axis>
    </joint>
    <link name='rotate_axis_link'>
      <pose frame=''>0 0 0.031 0 -0 0</pose>
      <inertial>
        <pose frame=''>0 -2.6e-05 0.597048 0 -0 0</pose>
        <mass>20.101</mass>
        <inertia>
          <ixx>4.75596</ixx>
          <ixy>-3.46983e-21</ixy>
          <ixz>2.12466e-37</ixz>
          <iyy>3.37345</iyy>
          <iyz>0.000351497</iyz>
          <izz>4.72355</izz>
        </inertia>
      </inertial>
      <collision name='rotate_axis_link_fixed_joint_lump__base_link_collision'>
        <pose frame=''>0 0 0.1 0 -0 0</pose>
        <geometry>
          <mesh>
            <scale>1 1 1</scale>
            <uri>model://gtrobot_base/meshes/base_link.STL</uri>
          </mesh>
        </geometry>
        <surface>
          <contact>
            <ode/>
          </contact>
          <friction>
            <ode/>
            <torsional>
              <ode/>
            </torsional>
          </friction>
          <bounce/>
        </surface>
        <max_contacts>10</max_contacts>
      </collision>
      <collision name='rotate_axis_link_fixed_joint_lump__upper_link_collision_1'>
        <pose frame=''>0 -0.531 1.259 -3.14159 -1.57079 -1.57079</pose>
        <geometry>
          <mesh>
            <scale>1 1 1</scale>
            <uri>model://gtrobot_base/meshes/upper.STL</uri>
          </mesh>
        </geometry>
        <surface>
          <contact>
            <ode/>
          </contact>
          <friction>
            <ode/>
            <torsional>
              <ode/>
            </torsional>
          </friction>
          <bounce/>
        </surface>
        <max_contacts>10</max_contacts>
      </collision>
      <visual name='rotate_axis_link_visual'>
        <pose frame=''>0 0 0 0 -0 0</pose>
        <geometry>
          <box>
            <size>0.68 1.35 0.01</size>
          </box>
        </geometry>
        <material>
          <script>
            <name>Gazebo/Blue</name>
            <uri>file://media/materials/scripts/gazebo.material</uri>
          </script>
        </material>
      </visual>
      <visual name='rotate_axis_link_fixed_joint_lump__base_link_visual_1'>
        <pose frame=''>0 0 0.1 0 -0 0</pose>
        <geometry>
          <mesh>
            <scale>1 1 1</scale>
            <uri>model://gtrobot_base/meshes/base_link.STL</uri>
          </mesh>
        </geometry>
        <material>
          <script>
            <name>Gazebo/Grey</name>
            <uri>file://media/materials/scripts/gazebo.material</uri>
          </script>
        </material>
      </visual>
      <visual name='rotate_axis_link_fixed_joint_lump__upper_link_visual_2'>
        <pose frame=''>0 -0.531 1.259 -3.14159 -1.57079 -1.57079</pose>
        <geometry>
          <mesh>
            <scale>1 1 1</scale>
            <uri>model://gtrobot_base/meshes/upper.STL</uri>
          </mesh>
        </geometry>
        <material>
          <script>
            <name>Gazebo/White</name>
            <uri>file://media/materials/scripts/gazebo.material</uri>
          </script>
        </material>
      </visual>
      <gravity>1</gravity>
      <velocity_decay/>
      <self_collide>0</self_collide>
      <enable_wind>0</enable_wind>
      <kinematic>0</kinematic>
    </link>
    <joint name='rotate_axis_joint' type='revolute'>
      <child>rotate_axis_link</child>
      <parent>y_axis_link</parent>
      <axis>
        <xyz>0 0 1</xyz>
        <limit>
          <lower>-1e+16</lower>
          <upper>1e+16</upper>
        </limit>
        <dynamics>
          <spring_reference>0</spring_reference>
          <spring_stiffness>0</spring_stiffness>
        </dynamics>
        <use_parent_model_frame>1</use_parent_model_frame>
      </axis>
    </joint>
    <link name='bl_caster_rotation_link'>
      <pose frame=''>-0.26 0.513 0.181 0 -0 0</pose>
      <inertial>
        <pose frame=''>0 0 0.07 0 -0 0</pose>
        <mass>0.05</mass>
        <inertia>
          <ixx>0.000563333</ixx>
          <ixy>0</ixy>
          <ixz>0</ixz>
          <iyy>0.000563333</iyy>
          <iyz>0</iyz>
          <izz>0.000563333</izz>
        </inertia>
      </inertial>
      <collision name='bl_caster_rotation_link_collision'>
        <pose frame=''>0 0 0 0 -0 0</pose>
        <geometry>
          <cylinder>
            <length>0.03</length>
            <radius>0.02</radius>
          </cylinder>
        </geometry>
        <surface>
          <contact>
            <ode/>
          </contact>
          <friction>
            <ode/>
            <torsional>
              <ode/>
            </torsional>
          </friction>
          <bounce/>
        </surface>
        <max_contacts>10</max_contacts>
      </collision>
      <visual name='bl_caster_rotation_link_visual'>
        <pose frame=''>0 0 0 0 -0 0</pose>
        <geometry>
          <cylinder>
            <length>0.03</length>
            <radius>0.02</radius>
          </cylinder>
        </geometry>
        <material>
          <script>
            <name>Gazebo/Red</name>
            <uri>file://media/materials/scripts/gazebo.material</uri>
          </script>
        </material>
      </visual>
      <gravity>1</gravity>
      <velocity_decay/>
      <self_collide>0</self_collide>
      <enable_wind>0</enable_wind>
      <kinematic>0</kinematic>
    </link>
    <joint name='bl_caster_rotation_joint' type='revolute'>
      <child>bl_caster_rotation_link</child>
      <parent>rotate_axis_link</parent>
      <axis>
        <xyz>0 0 1</xyz>
        <limit>
          <lower>-1e+16</lower>
          <upper>1e+16</upper>
        </limit>
        <dynamics>
          <damping>1</damping>
          <friction>1</friction>
          <spring_reference>0</spring_reference>
          <spring_stiffness>0</spring_stiffness>
        </dynamics>
        <use_parent_model_frame>1</use_parent_model_frame>
      </axis>
    </joint>
    <link name='bl_caster_wheel_link'>
      <pose frame=''>-0.26 0.513 0.111 0 -0 0</pose>
      <inertial>
        <pose frame=''>0 0 0 0 -0 0</pose>
        <mass>0.05</mass>
        <inertia>
          <ixx>2.83073e-05</ixx>
          <ixy>0</ixy>
          <ixz>0</ixz>
          <iyy>2.83073e-05</iyy>
          <iyz>0</iyz>
          <izz>5.64062e-05</izz>
        </inertia>
      </inertial>
      <collision name='bl_caster_wheel_link_collision'>
        <pose frame=''>0 0 0 1.5708 -0 0</pose>
        <geometry>
          <cylinder>
            <length>0.005</length>
            <radius>0.0475</radius>
          </cylinder>
        </geometry>
        <surface>
          <contact>
            <ode>
              <kp>1e+06</kp>
              <kd>1</kd>
            </ode>
          </contact>
          <friction>
            <ode/>
            <torsional>
              <ode/>
            </torsional>
          </friction>
          <bounce/>
        </surface>
        <max_contacts>10</max_contacts>
      </collision>
      <visual name='bl_caster_wheel_link_visual'>
        <pose frame=''>0 0 0 1.5708 -0 0</pose>
        <geometry>
          <cylinder>
            <length>0.005</length>
            <radius>0.0475</radius>
          </cylinder>
        </geometry>
        <material>
          <script>
            <uri>__default__</uri>
            <name>__default__</name>
          </script>
        </material>
      </visual>
      <gravity>1</gravity>
      <velocity_decay/>
      <gravity>1</gravity>
      <self_collide>0</self_collide>
      <enable_wind>0</enable_wind>
      <kinematic>0</kinematic>
    </link>
    <joint name='bl_caster_wheel_joint' type='revolute'>
      <child>bl_caster_wheel_link</child>
      <parent>bl_caster_rotation_link</parent>
      <axis>
        <xyz>0 1 0</xyz>
        <limit>
          <lower>-1e+16</lower>
          <upper>1e+16</upper>
        </limit>
        <dynamics>
          <damping>1</damping>
          <friction>1</friction>
          <spring_reference>0</spring_reference>
          <spring_stiffness>0</spring_stiffness>
        </dynamics>
        <use_parent_model_frame>1</use_parent_model_frame>
      </axis>
    </joint>
    <link name='br_caster_rotation_link'>
      <pose frame=''>-0.26 -0.513 0.181 0 -0 0</pose>
      <inertial>
        <pose frame=''>0 0 0.07 0 -0 0</pose>
        <mass>0.05</mass>
        <inertia>
          <ixx>0.000563333</ixx>
          <ixy>0</ixy>
          <ixz>0</ixz>
          <iyy>0.000563333</iyy>
          <iyz>0</iyz>
          <izz>0.000563333</izz>
        </inertia>
      </inertial>
      <collision name='br_caster_rotation_link_collision'>
        <pose frame=''>0 0 0 0 -0 0</pose>
        <geometry>
          <cylinder>
            <length>0.03</length>
            <radius>0.02</radius>
          </cylinder>
        </geometry>
        <surface>
          <contact>
            <ode/>
          </contact>
          <friction>
            <ode/>
            <torsional>
              <ode/>
            </torsional>
          </friction>
          <bounce/>
        </surface>
        <max_contacts>10</max_contacts>
      </collision>
      <visual name='br_caster_rotation_link_visual'>
        <pose frame=''>0 0 0 0 -0 0</pose>
        <geometry>
          <cylinder>
            <length>0.03</length>
            <radius>0.02</radius>
          </cylinder>
        </geometry>
        <material>
          <script>
            <name>Gazebo/Red</name>
            <uri>file://media/materials/scripts/gazebo.material</uri>
          </script>
        </material>
      </visual>
      <gravity>1</gravity>
      <velocity_decay/>
      <self_collide>0</self_collide>
      <enable_wind>0</enable_wind>
      <kinematic>0</kinematic>
    </link>
    <joint name='br_caster_rotation_joint' type='revolute'>
      <child>br_caster_rotation_link</child>
      <parent>rotate_axis_link</parent>
      <axis>
        <xyz>0 0 1</xyz>
        <limit>
          <lower>-1e+16</lower>
          <upper>1e+16</upper>
        </limit>
        <dynamics>
          <damping>1</damping>
          <friction>1</friction>
          <spring_reference>0</spring_reference>
          <spring_stiffness>0</spring_stiffness>
        </dynamics>
        <use_parent_model_frame>1</use_parent_model_frame>
      </axis>
    </joint>
    <link name='br_caster_wheel_link'>
      <pose frame=''>-0.26 -0.513 0.111 0 -0 0</pose>
      <inertial>
        <pose frame=''>0 0 0 0 -0 0</pose>
        <mass>0.05</mass>
        <inertia>
          <ixx>2.83073e-05</ixx>
          <ixy>0</ixy>
          <ixz>0</ixz>
          <iyy>2.83073e-05</iyy>
          <iyz>0</iyz>
          <izz>5.64062e-05</izz>
        </inertia>
      </inertial>
      <collision name='br_caster_wheel_link_collision'>
        <pose frame=''>0 0 0 1.5708 -0 0</pose>
        <geometry>
          <cylinder>
            <length>0.005</length>
            <radius>0.0475</radius>
          </cylinder>
        </geometry>
        <surface>
          <contact>
            <ode>
              <kp>1e+06</kp>
              <kd>1</kd>
            </ode>
          </contact>
          <friction>
            <ode/>
            <torsional>
              <ode/>
            </torsional>
          </friction>
          <bounce/>
        </surface>
        <max_contacts>10</max_contacts>
      </collision>
      <visual name='br_caster_wheel_link_visual'>
        <pose frame=''>0 0 0 1.5708 -0 0</pose>
        <geometry>
          <cylinder>
            <length>0.005</length>
            <radius>0.0475</radius>
          </cylinder>
        </geometry>
        <material>
          <script>
            <uri>__default__</uri>
            <name>__default__</name>
          </script>
        </material>
      </visual>
      <gravity>1</gravity>
      <velocity_decay/>
      <gravity>1</gravity>
      <self_collide>0</self_collide>
      <enable_wind>0</enable_wind>
      <kinematic>0</kinematic>
    </link>
    <joint name='br_caster_wheel_joint' type='revolute'>
      <child>br_caster_wheel_link</child>
      <parent>br_caster_rotation_link</parent>
      <axis>
        <xyz>0 1 0</xyz>
        <limit>
          <lower>-1e+16</lower>
          <upper>1e+16</upper>
        </limit>
        <dynamics>
          <damping>1</damping>
          <friction>1</friction>
          <spring_reference>0</spring_reference>
          <spring_stiffness>0</spring_stiffness>
        </dynamics>
        <use_parent_model_frame>1</use_parent_model_frame>
      </axis>
    </joint>
    <link name='fl_caster_rotation_link'>
      <pose frame=''>0.26 0.513 0.181 0 -0 0</pose>
      <inertial>
        <pose frame=''>0 0 0.07 0 -0 0</pose>
        <mass>0.05</mass>
        <inertia>
          <ixx>0.000563333</ixx>
          <ixy>0</ixy>
          <ixz>0</ixz>
          <iyy>0.000563333</iyy>
          <iyz>0</iyz>
          <izz>0.000563333</izz>
        </inertia>
      </inertial>
      <collision name='fl_caster_rotation_link_collision'>
        <pose frame=''>0 0 0 0 -0 0</pose>
        <geometry>
          <cylinder>
            <length>0.03</length>
            <radius>0.02</radius>
          </cylinder>
        </geometry>
        <surface>
          <contact>
            <ode/>
          </contact>
          <friction>
            <ode/>
            <torsional>
              <ode/>
            </torsional>
          </friction>
          <bounce/>
        </surface>
        <max_contacts>10</max_contacts>
      </collision>
      <visual name='fl_caster_rotation_link_visual'>
        <pose frame=''>0 0 0 0 -0 0</pose>
        <geometry>
          <cylinder>
            <length>0.03</length>
            <radius>0.02</radius>
          </cylinder>
        </geometry>
        <material>
          <script>
            <name>Gazebo/Red</name>
            <uri>file://media/materials/scripts/gazebo.material</uri>
          </script>
        </material>
      </visual>
      <gravity>1</gravity>
      <velocity_decay/>
      <self_collide>0</self_collide>
      <enable_wind>0</enable_wind>
      <kinematic>0</kinematic>
    </link>
    <joint name='fl_caster_rotation_joint' type='revolute'>
      <child>fl_caster_rotation_link</child>
      <parent>rotate_axis_link</parent>
      <axis>
        <xyz>0 0 1</xyz>
        <limit>
          <lower>-1e+16</lower>
          <upper>1e+16</upper>
        </limit>
        <dynamics>
          <damping>1</damping>
          <friction>1</friction>
          <spring_reference>0</spring_reference>
          <spring_stiffness>0</spring_stiffness>
        </dynamics>
        <use_parent_model_frame>1</use_parent_model_frame>
      </axis>
    </joint>
    <link name='fl_caster_wheel_link'>
      <pose frame=''>0.26 0.513 0.111 0 -0 0</pose>
      <inertial>
        <pose frame=''>0 0 0 0 -0 0</pose>
        <mass>0.05</mass>
        <inertia>
          <ixx>2.83073e-05</ixx>
          <ixy>0</ixy>
          <ixz>0</ixz>
          <iyy>2.83073e-05</iyy>
          <iyz>0</iyz>
          <izz>5.64062e-05</izz>
        </inertia>
      </inertial>
      <collision name='fl_caster_wheel_link_collision'>
        <pose frame=''>0 0 0 1.5708 -0 0</pose>
        <geometry>
          <cylinder>
            <length>0.005</length>
            <radius>0.0475</radius>
          </cylinder>
        </geometry>
        <surface>
          <contact>
            <ode>
              <kp>1e+06</kp>
              <kd>1</kd>
            </ode>
          </contact>
          <friction>
            <ode/>
            <torsional>
              <ode/>
            </torsional>
          </friction>
          <bounce/>
        </surface>
        <max_contacts>10</max_contacts>
      </collision>
      <visual name='fl_caster_wheel_link_visual'>
        <pose frame=''>0 0 0 1.5708 -0 0</pose>
        <geometry>
          <cylinder>
            <length>0.005</length>
            <radius>0.0475</radius>
          </cylinder>
        </geometry>
        <material>
          <script>
            <uri>__default__</uri>
            <name>__default__</name>
          </script>
        </material>
      </visual>
      <gravity>1</gravity>
      <velocity_decay/>
      <gravity>1</gravity>
      <self_collide>0</self_collide>
      <enable_wind>0</enable_wind>
      <kinematic>0</kinematic>
    </link>
    <joint name='fl_caster_wheel_joint' type='revolute'>
      <child>fl_caster_wheel_link</child>
      <parent>fl_caster_rotation_link</parent>
      <axis>
        <xyz>0 1 0</xyz>
        <limit>
          <lower>-1e+16</lower>
          <upper>1e+16</upper>
        </limit>
        <dynamics>
          <damping>1</damping>
          <friction>1</friction>
          <spring_reference>0</spring_reference>
          <spring_stiffness>0</spring_stiffness>
        </dynamics>
        <use_parent_model_frame>1</use_parent_model_frame>
      </axis>
    </joint>
    <link name='fr_caster_rotation_link'>
      <pose frame=''>0.26 -0.513 0.181 0 -0 0</pose>
      <inertial>
        <pose frame=''>0 0 0.07 0 -0 0</pose>
        <mass>0.05</mass>
        <inertia>
          <ixx>0.000563333</ixx>
          <ixy>0</ixy>
          <ixz>0</ixz>
          <iyy>0.000563333</iyy>
          <iyz>0</iyz>
          <izz>0.000563333</izz>
        </inertia>
      </inertial>
      <collision name='fr_caster_rotation_link_collision'>
        <pose frame=''>0 0 0 0 -0 0</pose>
        <geometry>
          <cylinder>
            <length>0.03</length>
            <radius>0.02</radius>
          </cylinder>
        </geometry>
        <surface>
          <contact>
            <ode/>
          </contact>
          <friction>
            <ode/>
            <torsional>
              <ode/>
            </torsional>
          </friction>
          <bounce/>
        </surface>
        <max_contacts>10</max_contacts>
      </collision>
      <visual name='fr_caster_rotation_link_visual'>
        <pose frame=''>0 0 0 0 -0 0</pose>
        <geometry>
          <cylinder>
            <length>0.03</length>
            <radius>0.02</radius>
          </cylinder>
        </geometry>
        <material>
          <script>
            <name>Gazebo/Red</name>
            <uri>file://media/materials/scripts/gazebo.material</uri>
          </script>
        </material>
      </visual>
      <gravity>1</gravity>
      <velocity_decay/>
      <self_collide>0</self_collide>
      <enable_wind>0</enable_wind>
      <kinematic>0</kinematic>
    </link>
    <joint name='fr_caster_rotation_joint' type='revolute'>
      <child>fr_caster_rotation_link</child>
      <parent>rotate_axis_link</parent>
      <axis>
        <xyz>0 0 1</xyz>
        <limit>
          <lower>-1e+16</lower>
          <upper>1e+16</upper>
        </limit>
        <dynamics>
          <damping>1</damping>
          <friction>1</friction>
          <spring_reference>0</spring_reference>
          <spring_stiffness>0</spring_stiffness>
        </dynamics>
        <use_parent_model_frame>1</use_parent_model_frame>
      </axis>
    </joint>
    <link name='fr_caster_wheel_link'>
      <pose frame=''>0.26 -0.513 0.111 0 -0 0</pose>
      <inertial>
        <pose frame=''>0 0 0 0 -0 0</pose>
        <mass>0.05</mass>
        <inertia>
          <ixx>2.83073e-05</ixx>
          <ixy>0</ixy>
          <ixz>0</ixz>
          <iyy>2.83073e-05</iyy>
          <iyz>0</iyz>
          <izz>5.64062e-05</izz>
        </inertia>
      </inertial>
      <collision name='fr_caster_wheel_link_collision'>
        <pose frame=''>0 0 0 1.5708 -0 0</pose>
        <geometry>
          <cylinder>
            <length>0.005</length>
            <radius>0.0475</radius>
          </cylinder>
        </geometry>
        <surface>
          <contact>
            <ode>
              <kp>1e+06</kp>
              <kd>1</kd>
            </ode>
          </contact>
          <friction>
            <ode/>
            <torsional>
              <ode/>
            </torsional>
          </friction>
          <bounce/>
        </surface>
        <max_contacts>10</max_contacts>
      </collision>
      <visual name='fr_caster_wheel_link_visual'>
        <pose frame=''>0 0 0 1.5708 -0 0</pose>
        <geometry>
          <cylinder>
            <length>0.005</length>
            <radius>0.0475</radius>
          </cylinder>
        </geometry>
        <material>
          <script>
            <uri>__default__</uri>
            <name>__default__</name>
          </script>
        </material>
      </visual>
      <gravity>1</gravity>
      <velocity_decay/>
      <gravity>1</gravity>
      <self_collide>0</self_collide>
      <enable_wind>0</enable_wind>
      <kinematic>0</kinematic>
    </link>
    <joint name='fr_caster_wheel_joint' type='revolute'>
      <child>fr_caster_wheel_link</child>
      <parent>fr_caster_rotation_link</parent>
      <axis>
        <xyz>0 1 0</xyz>
        <limit>
          <lower>-1e+16</lower>
          <upper>1e+16</upper>
        </limit>
        <dynamics>
          <damping>1</damping>
          <friction>1</friction>
          <spring_reference>0</spring_reference>
          <spring_stiffness>0</spring_stiffness>
        </dynamics>
        <use_parent_model_frame>1</use_parent_model_frame>
      </axis>
    </joint>
    <link name='left_caster_rotation_link'>
      <pose frame=''>0 0.25 0.181 0 -0 0</pose>
      <inertial>
        <pose frame=''>0 0 0.07 0 -0 0</pose>
        <mass>0.05</mass>
        <inertia>
          <ixx>0.000563333</ixx>
          <ixy>0</ixy>
          <ixz>0</ixz>
          <iyy>0.000563333</iyy>
          <iyz>0</iyz>
          <izz>0.000563333</izz>
        </inertia>
      </inertial>
      <collision name='left_caster_rotation_link_collision'>
        <pose frame=''>0 0 0 0 -0 0</pose>
        <geometry>
          <cylinder>
            <length>0.03</length>
            <radius>0.02</radius>
          </cylinder>
        </geometry>
        <surface>
          <contact>
            <ode/>
          </contact>
          <friction>
            <ode/>
            <torsional>
              <ode/>
            </torsional>
          </friction>
          <bounce/>
        </surface>
        <max_contacts>10</max_contacts>
      </collision>
      <visual name='left_caster_rotation_link_visual'>
        <pose frame=''>0 0 0 0 -0 0</pose>
        <geometry>
          <cylinder>
            <length>0.03</length>
            <radius>0.02</radius>
          </cylinder>
        </geometry>
        <material>
          <script>
            <name>Gazebo/Red</name>
            <uri>file://media/materials/scripts/gazebo.material</uri>
          </script>
        </material>
      </visual>
      <gravity>1</gravity>
      <velocity_decay/>
      <self_collide>0</self_collide>
      <enable_wind>0</enable_wind>
      <kinematic>0</kinematic>
    </link>
    <joint name='left_caster_rotation_joint' type='revolute'>
      <child>left_caster_rotation_link</child>
      <parent>rotate_axis_link</parent>
      <axis>
        <xyz>0 0 1</xyz>
        <limit>
          <lower>-1e+16</lower>
          <upper>1e+16</upper>
        </limit>
        <dynamics>
          <damping>1</damping>
          <friction>1</friction>
          <spring_reference>0</spring_reference>
          <spring_stiffness>0</spring_stiffness>
        </dynamics>
        <use_parent_model_frame>1</use_parent_model_frame>
      </axis>
    </joint>
    <link name='left_caster_wheel_link'>
      <pose frame=''>0 0.25 0.111 0 -0 0</pose>
      <inertial>
        <pose frame=''>0 0 0 0 -0 0</pose>
        <mass>0.05</mass>
        <inertia>
          <ixx>2.83073e-05</ixx>
          <ixy>0</ixy>
          <ixz>0</ixz>
          <iyy>2.83073e-05</iyy>
          <iyz>0</iyz>
          <izz>5.64062e-05</izz>
        </inertia>
      </inertial>
      <collision name='left_caster_wheel_link_collision'>
        <pose frame=''>0 0 0 1.5708 -0 0</pose>
        <geometry>
          <cylinder>
            <length>0.005</length>
            <radius>0.0475</radius>
          </cylinder>
        </geometry>
        <surface>
          <contact>
            <ode>
              <kp>1e+06</kp>
              <kd>1</kd>
            </ode>
          </contact>
          <friction>
            <ode/>
            <torsional>
              <ode/>
            </torsional>
          </friction>
          <bounce/>
        </surface>
        <max_contacts>10</max_contacts>
      </collision>
      <visual name='left_caster_wheel_link_visual'>
        <pose frame=''>0 0 0 1.5708 -0 0</pose>
        <geometry>
          <cylinder>
            <length>0.005</length>
            <radius>0.0475</radius>
          </cylinder>
        </geometry>
        <material>
          <script>
            <uri>__default__</uri>
            <name>__default__</name>
          </script>
        </material>
      </visual>
      <gravity>1</gravity>
      <velocity_decay/>
      <gravity>1</gravity>
      <self_collide>0</self_collide>
      <enable_wind>0</enable_wind>
      <kinematic>0</kinematic>
    </link>
    <joint name='left_caster_wheel_joint' type='revolute'>
      <child>left_caster_wheel_link</child>
      <parent>left_caster_rotation_link</parent>
      <axis>
        <xyz>0 1 0</xyz>
        <limit>
          <lower>-1e+16</lower>
          <upper>1e+16</upper>
        </limit>
        <dynamics>
          <damping>1</damping>
          <friction>1</friction>
          <spring_reference>0</spring_reference>
          <spring_stiffness>0</spring_stiffness>
        </dynamics>
        <use_parent_model_frame>1</use_parent_model_frame>
      </axis>
    </joint>
    <link name='right_caster_rotation_link'>
      <pose frame=''>0 -0.25 0.181 0 -0 0</pose>
      <inertial>
        <pose frame=''>0 0 0.07 0 -0 0</pose>
        <mass>0.05</mass>
        <inertia>
          <ixx>0.000563333</ixx>
          <ixy>0</ixy>
          <ixz>0</ixz>
          <iyy>0.000563333</iyy>
          <iyz>0</iyz>
          <izz>0.000563333</izz>
        </inertia>
      </inertial>
      <collision name='right_caster_rotation_link_collision'>
        <pose frame=''>0 0 0 0 -0 0</pose>
        <geometry>
          <cylinder>
            <length>0.03</length>
            <radius>0.02</radius>
          </cylinder>
        </geometry>
        <surface>
          <contact>
            <ode/>
          </contact>
          <friction>
            <ode/>
            <torsional>
              <ode/>
            </torsional>
          </friction>
          <bounce/>
        </surface>
        <max_contacts>10</max_contacts>
      </collision>
      <visual name='right_caster_rotation_link_visual'>
        <pose frame=''>0 0 0 0 -0 0</pose>
        <geometry>
          <cylinder>
            <length>0.03</length>
            <radius>0.02</radius>
          </cylinder>
        </geometry>
        <material>
          <script>
            <name>Gazebo/Red</name>
            <uri>file://media/materials/scripts/gazebo.material</uri>
          </script>
        </material>
      </visual>
      <gravity>1</gravity>
      <velocity_decay/>
      <self_collide>0</self_collide>
      <enable_wind>0</enable_wind>
      <kinematic>0</kinematic>
    </link>
    <joint name='right_caster_rotation_joint' type='revolute'>
      <child>right_caster_rotation_link</child>
      <parent>rotate_axis_link</parent>
      <axis>
        <xyz>0 0 1</xyz>
        <limit>
          <lower>-1e+16</lower>
          <upper>1e+16</upper>
        </limit>
        <dynamics>
          <damping>1</damping>
          <friction>1</friction>
          <spring_reference>0</spring_reference>
          <spring_stiffness>0</spring_stiffness>
        </dynamics>
        <use_parent_model_frame>1</use_parent_model_frame>
      </axis>
    </joint>
    <link name='right_caster_wheel_link'>
      <pose frame=''>0 -0.25 0.111 0 -0 0</pose>
      <inertial>
        <pose frame=''>0 0 0 0 -0 0</pose>
        <mass>0.05</mass>
        <inertia>
          <ixx>2.83073e-05</ixx>
          <ixy>0</ixy>
          <ixz>0</ixz>
          <iyy>2.83073e-05</iyy>
          <iyz>0</iyz>
          <izz>5.64062e-05</izz>
        </inertia>
      </inertial>
      <collision name='right_caster_wheel_link_collision'>
        <pose frame=''>0 0 0 1.5708 -0 0</pose>
        <geometry>
          <cylinder>
            <length>0.005</length>
            <radius>0.0475</radius>
          </cylinder>
        </geometry>
        <surface>
          <contact>
            <ode>
              <kp>1e+06</kp>
              <kd>1</kd>
            </ode>
          </contact>
          <friction>
            <ode/>
            <torsional>
              <ode/>
            </torsional>
          </friction>
          <bounce/>
        </surface>
        <max_contacts>10</max_contacts>
      </collision>
      <visual name='right_caster_wheel_link_visual'>
        <pose frame=''>0 0 0 1.5708 -0 0</pose>
        <geometry>
          <cylinder>
            <length>0.005</length>
            <radius>0.0475</radius>
          </cylinder>
        </geometry>
        <material>
          <script>
            <uri>__default__</uri>
            <name>__default__</name>
          </script>
        </material>
      </visual>
      <gravity>1</gravity>
      <velocity_decay/>
      <gravity>1</gravity>
      <self_collide>0</self_collide>
      <enable_wind>0</enable_wind>
      <kinematic>0</kinematic>
    </link>
    <joint name='right_caster_wheel_joint' type='revolute'>
      <child>right_caster_wheel_link</child>
      <parent>right_caster_rotation_link</parent>
      <axis>
        <xyz>0 1 0</xyz>
        <limit>
          <lower>-1e+16</lower>
          <upper>1e+16</upper>
        </limit>
        <dynamics>
          <damping>1</damping>
          <friction>1</friction>
          <spring_reference>0</spring_reference>
          <spring_stiffness>0</spring_stiffness>
        </dynamics>
        <use_parent_model_frame>1</use_parent_model_frame>
      </axis>
    </joint>
    <plugin name='ros_control' filename='libgazebo_ros_control.so'>
      <robotSimType>gazebo_ros_control/DefaultRobotHWSim</robotSimType>
      <legacyModeNS>1</legacyModeNS>
      <robotNamespace>/</robotNamespace>
    </plugin>
    <static>0</static>
    <pose frame=''>0 0 0 0 -0 0</pose>
  </model>
</sdf>