<?xml version='1.0'?>
<sdf version='1.6'>
  <world name='default'>
    <light name='sun' type='directional'>
      <cast_shadows>1</cast_shadows>
      <pose frame=''>0 0 10 0 -0 0</pose>
      <diffuse>0.8 0.8 0.8 1</diffuse>
      <specular>0.2 0.2 0.2 1</specular>
      <attenuation>
        <range>1000</range>
        <constant>0.9</constant>
        <linear>0.01</linear>
        <quadratic>0.001</quadratic>
      </attenuation>
      <direction>-0.5 0.1 -0.9</direction>
    </light>
    <model name='ground_plane'>
      <static>1</static>
      <link name='link'>
        <collision name='collision'>
          <geometry>
            <plane>
              <normal>0 0 1</normal>
              <size>100 100</size>
            </plane>
          </geometry>
          <surface>
            <friction>
              <ode>
                <mu>100</mu>
                <mu2>50</mu2>
              </ode>
              <torsional>
                <ode/>
              </torsional>
            </friction>
            <contact>
              <ode/>
            </contact>
            <bounce/>
          </surface>
          <max_contacts>10</max_contacts>
        </collision>
        <visual name='visual'>
          <cast_shadows>0</cast_shadows>
          <geometry>
            <plane>
              <normal>0 0 1</normal>
              <size>100 100</size>
            </plane>
          </geometry>
          <material>
            <script>
              <uri>file://media/materials/scripts/gazebo.material</uri>
              <name>Gazebo/Grey</name>
            </script>
          </material>
        </visual>
        <self_collide>0</self_collide>
        <enable_wind>0</enable_wind>
        <kinematic>0</kinematic>
      </link>
    </model>
    <gravity>0 0 -9.8</gravity>
    <magnetic_field>6e-06 2.3e-05 -4.2e-05</magnetic_field>
    <atmosphere type='adiabatic'/>
    <physics name='default_physics' default='0' type='ode'>
      <max_step_size>0.001</max_step_size>
      <real_time_factor>1</real_time_factor>
      <real_time_update_rate>1000</real_time_update_rate>
    </physics>
    <scene>
      <ambient>0.4 0.4 0.4 1</ambient>
      <background>0.7 0.7 0.7 1</background>
      <shadows>1</shadows>
    </scene>
    <audio>
      <device>default</device>
    </audio>
    <wind/>
    <spherical_coordinates>
      <surface_model>EARTH_WGS84</surface_model>
      <latitude_deg>0</latitude_deg>
      <longitude_deg>0</longitude_deg>
      <elevation>0</elevation>
      <heading_deg>0</heading_deg>
    </spherical_coordinates>
    <model name='xianquzhe'>
      <link name='base_footprint'>
        <pose frame=''>0 0 0 0 -0 0</pose>
        <inertial>
          <pose frame=''>0 0 0.001 0 -0 0</pose>
          <mass>10</mass>
          <inertia>
            <ixx>1.51875</ixx>
            <ixy>0</ixy>
            <ixz>0</ixz>
            <iyy>0.385334</iyy>
            <iyz>0</iyz>
            <izz>1.90408</izz>
          </inertia>
        </inertial>
        <visual name='base_footprint_visual'>
          <pose frame=''>0 0 0 0 -0 0</pose>
          <geometry>
            <box>
              <size>0.001 0.001 0.001</size>
            </box>
          </geometry>
          <material>
            <script>
              <name>Gazebo/White</name>
              <uri>file://media/materials/scripts/gazebo.material</uri>
            </script>
          </material>
        </visual>
        <visual name='base_footprint_fixed_joint_lump__fixed_link_visual_1'>
          <pose frame=''>0 0 0.001 0 -0 0</pose>
          <geometry>
            <box>
              <size>0.68 1.35 0.001</size>
            </box>
          </geometry>
          <material>
            <script>
              <name>Gazebo/White</name>
              <uri>file://media/materials/scripts/gazebo.material</uri>
            </script>
          </material>
        </visual>
        <velocity_decay/>
        <gravity>0</gravity>
        <gravity>1</gravity>
        <velocity_decay/>
        <gravity>0</gravity>
        <self_collide>0</self_collide>
        <enable_wind>0</enable_wind>
        <kinematic>0</kinematic>
      </link>
      <link name='x_axis_link'>
        <pose frame=''>0 0 0.011 0 -0 0</pose>
        <inertial>
          <pose frame=''>0 0 0 0 -0 0</pose>
          <mass>0.1</mass>
          <inertia>
            <ixx>0.0151883</ixx>
            <ixy>0</ixy>
            <ixz>0</ixz>
            <iyy>0.00385417</iyy>
            <iyz>0</iyz>
            <izz>0.0190408</izz>
          </inertia>
        </inertial>
        <visual name='x_axis_link_visual'>
          <pose frame=''>0 0 0 0 -0 0</pose>
          <geometry>
            <box>
              <size>0.68 1.35 0.01</size>
            </box>
          </geometry>
          <material>
            <script>
              <name>Gazebo/Red</name>
              <uri>file://media/materials/scripts/gazebo.material</uri>
            </script>
          </material>
        </visual>
        <gravity>1</gravity>
        <velocity_decay/>
        <gravity>0</gravity>
        <self_collide>0</self_collide>
        <enable_wind>0</enable_wind>
        <kinematic>0</kinematic>
      </link>
      <joint name='x_axis_joint' type='prismatic'>
        <child>x_axis_link</child>
        <parent>base_footprint</parent>
        <axis>
          <xyz>1 0 0</xyz>
          <limit>
            <lower>-5</lower>
            <upper>5</upper>
            <effort>10000</effort>
            <velocity>1</velocity>
          </limit>
          <dynamics>
            <spring_reference>0</spring_reference>
            <spring_stiffness>0</spring_stiffness>
          </dynamics>
          <use_parent_model_frame>1</use_parent_model_frame>
        </axis>
      </joint>
      <link name='y_axis_link'>
        <pose frame=''>0 0 0.021 0 -0 0</pose>
        <inertial>
          <pose frame=''>0 0 0 0 -0 0</pose>
          <mass>0.1</mass>
          <inertia>
            <ixx>0.0151883</ixx>
            <ixy>0</ixy>
            <ixz>0</ixz>
            <iyy>0.00385417</iyy>
            <iyz>0</iyz>
            <izz>0.0190408</izz>
          </inertia>
        </inertial>
        <visual name='y_axis_link_visual'>
          <pose frame=''>0 0 0 0 -0 0</pose>
          <geometry>
            <box>
              <size>0.68 1.35 0.01</size>
            </box>
          </geometry>
          <material>
            <script>
              <name>Gazebo/Green</name>
              <uri>file://media/materials/scripts/gazebo.material</uri>
            </script>
          </material>
        </visual>
        <gravity>1</gravity>
        <velocity_decay/>
        <gravity>0</gravity>
        <self_collide>0</self_collide>
        <enable_wind>0</enable_wind>
        <kinematic>0</kinematic>
      </link>
      <joint name='y_axis_joint' type='prismatic'>
        <child>y_axis_link</child>
        <parent>x_axis_link</parent>
        <axis>
          <xyz>0 1 0</xyz>
          <limit>
            <lower>-5</lower>
            <upper>5</upper>
            <effort>10000</effort>
            <velocity>1</velocity>
          </limit>
          <dynamics>
            <spring_reference>0</spring_reference>
            <spring_stiffness>0</spring_stiffness>
          </dynamics>
          <use_parent_model_frame>1</use_parent_model_frame>
        </axis>
      </joint>
      <link name='rotate_axis_link'>
        <pose frame=''>0 0 0.031 0 -0 0</pose>
        <inertial>
          <pose frame=''>0 -2.7e-05 0.597049 0 -0 0</pose>
          <mass>20.101</mass>
          <inertia>
            <ixx>4.75598</ixx>
            <ixy>-3.46814e-21</ixy>
            <ixz>2.12362e-37</ixz>
            <iyy>3.37347</iyy>
            <iyz>0.000365556</iyz>
            <izz>4.72356</izz>
          </inertia>
        </inertial>
        <collision name='rotate_axis_link_fixed_joint_lump__base_link_collision'>
          <pose frame=''>0 0 0.1 0 -0 0</pose>
          <geometry>
            <mesh>
              <scale>1 1 1</scale>
              <uri>/home/jiang/ppr_ws/src/gt_sim/gt_description/meshes/gtrobot_base/base_link.STL</uri>
            </mesh>
          </geometry>
          <surface>
            <contact>
              <ode/>
            </contact>
            <friction>
              <ode/>
              <torsional>
                <ode/>
              </torsional>
            </friction>
            <bounce/>
          </surface>
          <max_contacts>10</max_contacts>
        </collision>
        <collision name='rotate_axis_link_fixed_joint_lump__upper_link_collision_1'>
          <pose frame=''>0 -0.531 1.259 -3.14159 -1.57079 -1.57079</pose>
          <geometry>
            <mesh>
              <scale>1 1 1</scale>
              <uri>/home/jiang/ppr_ws/src/gt_sim/gt_description/meshes/gtrobot_base/upper.STL</uri>
            </mesh>
          </geometry>
          <surface>
            <contact>
              <ode/>
            </contact>
            <friction>
              <ode/>
              <torsional>
                <ode/>
              </torsional>
            </friction>
            <bounce/>
          </surface>
          <max_contacts>10</max_contacts>
        </collision>
        <collision name='rotate_axis_link_fixed_joint_lump__arm_base_link_collision_2'>
          <pose frame=''>0 -0.531 1.259 1.5708 0.785398 -0</pose>
          <geometry>
            <mesh>
              <scale>1 1 1</scale>
              <uri>/home/jiang/ppr_ws/src/gt_sim/gt_description/meshes/gtrobot_arm/collision/base.stl</uri>
            </mesh>
          </geometry>
          <max_contacts>10</max_contacts>
          <surface>
            <contact>
              <ode/>
            </contact>
            <bounce/>
            <friction>
              <torsional>
                <ode/>
              </torsional>
              <ode/>
            </friction>
          </surface>
        </collision>
        <visual name='rotate_axis_link_visual'>
          <pose frame=''>0 0 0 0 -0 0</pose>
          <geometry>
            <box>
              <size>0.68 1.35 0.01</size>
            </box>
          </geometry>
          <material>
            <script>
              <name>Gazebo/Blue</name>
              <uri>file://media/materials/scripts/gazebo.material</uri>
            </script>
          </material>
        </visual>
        <visual name='rotate_axis_link_fixed_joint_lump__base_link_visual_1'>
          <pose frame=''>0 0 0.1 0 -0 0</pose>
          <geometry>
            <mesh>
              <scale>1 1 1</scale>
              <uri>/home/jiang/ppr_ws/src/gt_sim/gt_description/meshes/gtrobot_base/base_link.STL</uri>
            </mesh>
          </geometry>
          <material>
            <script>
              <name>Gazebo/Grey</name>
              <uri>file://media/materials/scripts/gazebo.material</uri>
            </script>
          </material>
        </visual>
        <visual name='rotate_axis_link_fixed_joint_lump__upper_link_visual_2'>
          <pose frame=''>0 -0.531 1.259 -3.14159 -1.57079 -1.57079</pose>
          <geometry>
            <mesh>
              <scale>1 1 1</scale>
              <uri>/home/jiang/ppr_ws/src/gt_sim/gt_description/meshes/gtrobot_base/upper.STL</uri>
            </mesh>
          </geometry>
          <material>
            <script>
              <name>Gazebo/White</name>
              <uri>file://media/materials/scripts/gazebo.material</uri>
            </script>
          </material>
        </visual>
        <visual name='rotate_axis_link_fixed_joint_lump__arm_base_link_visual_3'>
          <pose frame=''>0 -0.531 1.259 1.5708 0.785398 -0</pose>
          <geometry>
            <mesh>
              <scale>1 1 1</scale>
              <uri>/home/jiang/ppr_ws/src/gt_sim/gt_description/meshes/gtrobot_arm/visual/base.dae</uri>
            </mesh>
          </geometry>
        </visual>
        <velocity_decay/>
        <gravity>1</gravity>
        <velocity_decay/>
        <gravity>1</gravity>
        <gravity>1</gravity>
        <velocity_decay/>
        <gravity>0</gravity>
        <self_collide>0</self_collide>
        <enable_wind>0</enable_wind>
        <kinematic>0</kinematic>
      </link>
      <joint name='rotate_axis_joint' type='revolute'>
        <child>rotate_axis_link</child>
        <parent>y_axis_link</parent>
        <axis>
          <xyz>0 0 1</xyz>
          <limit>
            <lower>-1e+16</lower>
            <upper>1e+16</upper>
          </limit>
          <dynamics>
            <spring_reference>0</spring_reference>
            <spring_stiffness>0</spring_stiffness>
          </dynamics>
          <use_parent_model_frame>1</use_parent_model_frame>
        </axis>
      </joint>
      <link name='bl_caster_rotation_link'>
        <pose frame=''>-0.26 0.513 0.181 0 -0 0</pose>
        <inertial>
          <pose frame=''>0 0 0.07 0 -0 0</pose>
          <mass>0.05</mass>
          <inertia>
            <ixx>0.000563333</ixx>
            <ixy>0</ixy>
            <ixz>0</ixz>
            <iyy>0.000563333</iyy>
            <iyz>0</iyz>
            <izz>0.000563333</izz>
          </inertia>
        </inertial>
        <collision name='bl_caster_rotation_link_collision'>
          <pose frame=''>0 0 0 0 -0 0</pose>
          <geometry>
            <cylinder>
              <length>0.03</length>
              <radius>0.02</radius>
            </cylinder>
          </geometry>
          <surface>
            <contact>
              <ode/>
            </contact>
            <friction>
              <ode/>
              <torsional>
                <ode/>
              </torsional>
            </friction>
            <bounce/>
          </surface>
          <max_contacts>10</max_contacts>
        </collision>
        <visual name='bl_caster_rotation_link_visual'>
          <pose frame=''>0 0 0 0 -0 0</pose>
          <geometry>
            <cylinder>
              <length>0.03</length>
              <radius>0.02</radius>
            </cylinder>
          </geometry>
          <material>
            <script>
              <name>Gazebo/Red</name>
              <uri>file://media/materials/scripts/gazebo.material</uri>
            </script>
          </material>
        </visual>
        <gravity>1</gravity>
        <velocity_decay/>
        <self_collide>0</self_collide>
        <enable_wind>0</enable_wind>
        <kinematic>0</kinematic>
      </link>
      <joint name='bl_caster_rotation_joint' type='revolute'>
        <child>bl_caster_rotation_link</child>
        <parent>rotate_axis_link</parent>
        <axis>
          <xyz>0 0 1</xyz>
          <limit>
            <lower>-1e+16</lower>
            <upper>1e+16</upper>
          </limit>
          <dynamics>
            <damping>1</damping>
            <friction>1</friction>
            <spring_reference>0</spring_reference>
            <spring_stiffness>0</spring_stiffness>
          </dynamics>
          <use_parent_model_frame>1</use_parent_model_frame>
        </axis>
      </joint>
      <link name='bl_caster_wheel_link'>
        <pose frame=''>-0.26 0.513 0.111 0 -0 0</pose>
        <inertial>
          <pose frame=''>0 0 0 0 -0 0</pose>
          <mass>0.05</mass>
          <inertia>
            <ixx>2.83073e-05</ixx>
            <ixy>0</ixy>
            <ixz>0</ixz>
            <iyy>2.83073e-05</iyy>
            <iyz>0</iyz>
            <izz>5.64062e-05</izz>
          </inertia>
        </inertial>
        <collision name='bl_caster_wheel_link_collision'>
          <pose frame=''>0 0 0 1.5708 -0 0</pose>
          <geometry>
            <cylinder>
              <length>0.005</length>
              <radius>0.0475</radius>
            </cylinder>
          </geometry>
          <surface>
            <contact>
              <ode>
                <kp>1e+06</kp>
                <kd>1</kd>
              </ode>
            </contact>
            <friction>
              <ode/>
              <torsional>
                <ode/>
              </torsional>
            </friction>
            <bounce/>
          </surface>
          <max_contacts>10</max_contacts>
        </collision>
        <visual name='bl_caster_wheel_link_visual'>
          <pose frame=''>0 0 0 1.5708 -0 0</pose>
          <geometry>
            <cylinder>
              <length>0.005</length>
              <radius>0.0475</radius>
            </cylinder>
          </geometry>
          <material>
            <script>
              <uri>__default__</uri>
              <name>__default__</name>
            </script>
          </material>
        </visual>
        <gravity>1</gravity>
        <velocity_decay/>
        <gravity>1</gravity>
        <self_collide>0</self_collide>
        <enable_wind>0</enable_wind>
        <kinematic>0</kinematic>
      </link>
      <joint name='bl_caster_wheel_joint' type='revolute'>
        <child>bl_caster_wheel_link</child>
        <parent>bl_caster_rotation_link</parent>
        <axis>
          <xyz>0 1 0</xyz>
          <limit>
            <lower>-1e+16</lower>
            <upper>1e+16</upper>
          </limit>
          <dynamics>
            <damping>1</damping>
            <friction>1</friction>
            <spring_reference>0</spring_reference>
            <spring_stiffness>0</spring_stiffness>
          </dynamics>
          <use_parent_model_frame>1</use_parent_model_frame>
        </axis>
      </joint>
      <link name='br_caster_rotation_link'>
        <pose frame=''>-0.26 -0.513 0.181 0 -0 0</pose>
        <inertial>
          <pose frame=''>0 0 0.07 0 -0 0</pose>
          <mass>0.05</mass>
          <inertia>
            <ixx>0.000563333</ixx>
            <ixy>0</ixy>
            <ixz>0</ixz>
            <iyy>0.000563333</iyy>
            <iyz>0</iyz>
            <izz>0.000563333</izz>
          </inertia>
        </inertial>
        <collision name='br_caster_rotation_link_collision'>
          <pose frame=''>0 0 0 0 -0 0</pose>
          <geometry>
            <cylinder>
              <length>0.03</length>
              <radius>0.02</radius>
            </cylinder>
          </geometry>
          <surface>
            <contact>
              <ode/>
            </contact>
            <friction>
              <ode/>
              <torsional>
                <ode/>
              </torsional>
            </friction>
            <bounce/>
          </surface>
          <max_contacts>10</max_contacts>
        </collision>
        <visual name='br_caster_rotation_link_visual'>
          <pose frame=''>0 0 0 0 -0 0</pose>
          <geometry>
            <cylinder>
              <length>0.03</length>
              <radius>0.02</radius>
            </cylinder>
          </geometry>
          <material>
            <script>
              <name>Gazebo/Red</name>
              <uri>file://media/materials/scripts/gazebo.material</uri>
            </script>
          </material>
        </visual>
        <gravity>1</gravity>
        <velocity_decay/>
        <self_collide>0</self_collide>
        <enable_wind>0</enable_wind>
        <kinematic>0</kinematic>
      </link>
      <joint name='br_caster_rotation_joint' type='revolute'>
        <child>br_caster_rotation_link</child>
        <parent>rotate_axis_link</parent>
        <axis>
          <xyz>0 0 1</xyz>
          <limit>
            <lower>-1e+16</lower>
            <upper>1e+16</upper>
          </limit>
          <dynamics>
            <damping>1</damping>
            <friction>1</friction>
            <spring_reference>0</spring_reference>
            <spring_stiffness>0</spring_stiffness>
          </dynamics>
          <use_parent_model_frame>1</use_parent_model_frame>
        </axis>
      </joint>
      <link name='br_caster_wheel_link'>
        <pose frame=''>-0.26 -0.513 0.111 0 -0 0</pose>
        <inertial>
          <pose frame=''>0 0 0 0 -0 0</pose>
          <mass>0.05</mass>
          <inertia>
            <ixx>2.83073e-05</ixx>
            <ixy>0</ixy>
            <ixz>0</ixz>
            <iyy>2.83073e-05</iyy>
            <iyz>0</iyz>
            <izz>5.64062e-05</izz>
          </inertia>
        </inertial>
        <collision name='br_caster_wheel_link_collision'>
          <pose frame=''>0 0 0 1.5708 -0 0</pose>
          <geometry>
            <cylinder>
              <length>0.005</length>
              <radius>0.0475</radius>
            </cylinder>
          </geometry>
          <surface>
            <contact>
              <ode>
                <kp>1e+06</kp>
                <kd>1</kd>
              </ode>
            </contact>
            <friction>
              <ode/>
              <torsional>
                <ode/>
              </torsional>
            </friction>
            <bounce/>
          </surface>
          <max_contacts>10</max_contacts>
        </collision>
        <visual name='br_caster_wheel_link_visual'>
          <pose frame=''>0 0 0 1.5708 -0 0</pose>
          <geometry>
            <cylinder>
              <length>0.005</length>
              <radius>0.0475</radius>
            </cylinder>
          </geometry>
          <material>
            <script>
              <uri>__default__</uri>
              <name>__default__</name>
            </script>
          </material>
        </visual>
        <gravity>1</gravity>
        <velocity_decay/>
        <gravity>1</gravity>
        <self_collide>0</self_collide>
        <enable_wind>0</enable_wind>
        <kinematic>0</kinematic>
      </link>
      <joint name='br_caster_wheel_joint' type='revolute'>
        <child>br_caster_wheel_link</child>
        <parent>br_caster_rotation_link</parent>
        <axis>
          <xyz>0 1 0</xyz>
          <limit>
            <lower>-1e+16</lower>
            <upper>1e+16</upper>
          </limit>
          <dynamics>
            <damping>1</damping>
            <friction>1</friction>
            <spring_reference>0</spring_reference>
            <spring_stiffness>0</spring_stiffness>
          </dynamics>
          <use_parent_model_frame>1</use_parent_model_frame>
        </axis>
      </joint>
      <link name='fl_caster_rotation_link'>
        <pose frame=''>0.26 0.513 0.181 0 -0 0</pose>
        <inertial>
          <pose frame=''>0 0 0.07 0 -0 0</pose>
          <mass>0.05</mass>
          <inertia>
            <ixx>0.000563333</ixx>
            <ixy>0</ixy>
            <ixz>0</ixz>
            <iyy>0.000563333</iyy>
            <iyz>0</iyz>
            <izz>0.000563333</izz>
          </inertia>
        </inertial>
        <collision name='fl_caster_rotation_link_collision'>
          <pose frame=''>0 0 0 0 -0 0</pose>
          <geometry>
            <cylinder>
              <length>0.03</length>
              <radius>0.02</radius>
            </cylinder>
          </geometry>
          <surface>
            <contact>
              <ode/>
            </contact>
            <friction>
              <ode/>
              <torsional>
                <ode/>
              </torsional>
            </friction>
            <bounce/>
          </surface>
          <max_contacts>10</max_contacts>
        </collision>
        <visual name='fl_caster_rotation_link_visual'>
          <pose frame=''>0 0 0 0 -0 0</pose>
          <geometry>
            <cylinder>
              <length>0.03</length>
              <radius>0.02</radius>
            </cylinder>
          </geometry>
          <material>
            <script>
              <name>Gazebo/Red</name>
              <uri>file://media/materials/scripts/gazebo.material</uri>
            </script>
          </material>
        </visual>
        <gravity>1</gravity>
        <velocity_decay/>
        <self_collide>0</self_collide>
        <enable_wind>0</enable_wind>
        <kinematic>0</kinematic>
      </link>
      <joint name='fl_caster_rotation_joint' type='revolute'>
        <child>fl_caster_rotation_link</child>
        <parent>rotate_axis_link</parent>
        <axis>
          <xyz>0 0 1</xyz>
          <limit>
            <lower>-1e+16</lower>
            <upper>1e+16</upper>
          </limit>
          <dynamics>
            <damping>1</damping>
            <friction>1</friction>
            <spring_reference>0</spring_reference>
            <spring_stiffness>0</spring_stiffness>
          </dynamics>
          <use_parent_model_frame>1</use_parent_model_frame>
        </axis>
      </joint>
      <link name='fl_caster_wheel_link'>
        <pose frame=''>0.26 0.513 0.111 0 -0 0</pose>
        <inertial>
          <pose frame=''>0 0 0 0 -0 0</pose>
          <mass>0.05</mass>
          <inertia>
            <ixx>2.83073e-05</ixx>
            <ixy>0</ixy>
            <ixz>0</ixz>
            <iyy>2.83073e-05</iyy>
            <iyz>0</iyz>
            <izz>5.64062e-05</izz>
          </inertia>
        </inertial>
        <collision name='fl_caster_wheel_link_collision'>
          <pose frame=''>0 0 0 1.5708 -0 0</pose>
          <geometry>
            <cylinder>
              <length>0.005</length>
              <radius>0.0475</radius>
            </cylinder>
          </geometry>
          <surface>
            <contact>
              <ode>
                <kp>1e+06</kp>
                <kd>1</kd>
              </ode>
            </contact>
            <friction>
              <ode/>
              <torsional>
                <ode/>
              </torsional>
            </friction>
            <bounce/>
          </surface>
          <max_contacts>10</max_contacts>
        </collision>
        <visual name='fl_caster_wheel_link_visual'>
          <pose frame=''>0 0 0 1.5708 -0 0</pose>
          <geometry>
            <cylinder>
              <length>0.005</length>
              <radius>0.0475</radius>
            </cylinder>
          </geometry>
          <material>
            <script>
              <uri>__default__</uri>
              <name>__default__</name>
            </script>
          </material>
        </visual>
        <gravity>1</gravity>
        <velocity_decay/>
        <gravity>1</gravity>
        <self_collide>0</self_collide>
        <enable_wind>0</enable_wind>
        <kinematic>0</kinematic>
      </link>
      <joint name='fl_caster_wheel_joint' type='revolute'>
        <child>fl_caster_wheel_link</child>
        <parent>fl_caster_rotation_link</parent>
        <axis>
          <xyz>0 1 0</xyz>
          <limit>
            <lower>-1e+16</lower>
            <upper>1e+16</upper>
          </limit>
          <dynamics>
            <damping>1</damping>
            <friction>1</friction>
            <spring_reference>0</spring_reference>
            <spring_stiffness>0</spring_stiffness>
          </dynamics>
          <use_parent_model_frame>1</use_parent_model_frame>
        </axis>
      </joint>
      <link name='fr_caster_rotation_link'>
        <pose frame=''>0.26 -0.513 0.181 0 -0 0</pose>
        <inertial>
          <pose frame=''>0 0 0.07 0 -0 0</pose>
          <mass>0.05</mass>
          <inertia>
            <ixx>0.000563333</ixx>
            <ixy>0</ixy>
            <ixz>0</ixz>
            <iyy>0.000563333</iyy>
            <iyz>0</iyz>
            <izz>0.000563333</izz>
          </inertia>
        </inertial>
        <collision name='fr_caster_rotation_link_collision'>
          <pose frame=''>0 0 0 0 -0 0</pose>
          <geometry>
            <cylinder>
              <length>0.03</length>
              <radius>0.02</radius>
            </cylinder>
          </geometry>
          <surface>
            <contact>
              <ode/>
            </contact>
            <friction>
              <ode/>
              <torsional>
                <ode/>
              </torsional>
            </friction>
            <bounce/>
          </surface>
          <max_contacts>10</max_contacts>
        </collision>
        <visual name='fr_caster_rotation_link_visual'>
          <pose frame=''>0 0 0 0 -0 0</pose>
          <geometry>
            <cylinder>
              <length>0.03</length>
              <radius>0.02</radius>
            </cylinder>
          </geometry>
          <material>
            <script>
              <name>Gazebo/Red</name>
              <uri>file://media/materials/scripts/gazebo.material</uri>
            </script>
          </material>
        </visual>
        <gravity>1</gravity>
        <velocity_decay/>
        <self_collide>0</self_collide>
        <enable_wind>0</enable_wind>
        <kinematic>0</kinematic>
      </link>
      <joint name='fr_caster_rotation_joint' type='revolute'>
        <child>fr_caster_rotation_link</child>
        <parent>rotate_axis_link</parent>
        <axis>
          <xyz>0 0 1</xyz>
          <limit>
            <lower>-1e+16</lower>
            <upper>1e+16</upper>
          </limit>
          <dynamics>
            <damping>1</damping>
            <friction>1</friction>
            <spring_reference>0</spring_reference>
            <spring_stiffness>0</spring_stiffness>
          </dynamics>
          <use_parent_model_frame>1</use_parent_model_frame>
        </axis>
      </joint>
      <link name='fr_caster_wheel_link'>
        <pose frame=''>0.26 -0.513 0.111 0 -0 0</pose>
        <inertial>
          <pose frame=''>0 0 0 0 -0 0</pose>
          <mass>0.05</mass>
          <inertia>
            <ixx>2.83073e-05</ixx>
            <ixy>0</ixy>
            <ixz>0</ixz>
            <iyy>2.83073e-05</iyy>
            <iyz>0</iyz>
            <izz>5.64062e-05</izz>
          </inertia>
        </inertial>
        <collision name='fr_caster_wheel_link_collision'>
          <pose frame=''>0 0 0 1.5708 -0 0</pose>
          <geometry>
            <cylinder>
              <length>0.005</length>
              <radius>0.0475</radius>
            </cylinder>
          </geometry>
          <surface>
            <contact>
              <ode>
                <kp>1e+06</kp>
                <kd>1</kd>
              </ode>
            </contact>
            <friction>
              <ode/>
              <torsional>
                <ode/>
              </torsional>
            </friction>
            <bounce/>
          </surface>
          <max_contacts>10</max_contacts>
        </collision>
        <visual name='fr_caster_wheel_link_visual'>
          <pose frame=''>0 0 0 1.5708 -0 0</pose>
          <geometry>
            <cylinder>
              <length>0.005</length>
              <radius>0.0475</radius>
            </cylinder>
          </geometry>
          <material>
            <script>
              <uri>__default__</uri>
              <name>__default__</name>
            </script>
          </material>
        </visual>
        <gravity>1</gravity>
        <velocity_decay/>
        <gravity>1</gravity>
        <self_collide>0</self_collide>
        <enable_wind>0</enable_wind>
        <kinematic>0</kinematic>
      </link>
      <joint name='fr_caster_wheel_joint' type='revolute'>
        <child>fr_caster_wheel_link</child>
        <parent>fr_caster_rotation_link</parent>
        <axis>
          <xyz>0 1 0</xyz>
          <limit>
            <lower>-1e+16</lower>
            <upper>1e+16</upper>
          </limit>
          <dynamics>
            <damping>1</damping>
            <friction>1</friction>
            <spring_reference>0</spring_reference>
            <spring_stiffness>0</spring_stiffness>
          </dynamics>
          <use_parent_model_frame>1</use_parent_model_frame>
        </axis>
      </joint>
      <link name='left_caster_rotation_link'>
        <pose frame=''>0 0.25 0.181 0 -0 0</pose>
        <inertial>
          <pose frame=''>0 0 0.07 0 -0 0</pose>
          <mass>0.05</mass>
          <inertia>
            <ixx>0.000563333</ixx>
            <ixy>0</ixy>
            <ixz>0</ixz>
            <iyy>0.000563333</iyy>
            <iyz>0</iyz>
            <izz>0.000563333</izz>
          </inertia>
        </inertial>
        <collision name='left_caster_rotation_link_collision'>
          <pose frame=''>0 0 0 0 -0 0</pose>
          <geometry>
            <cylinder>
              <length>0.03</length>
              <radius>0.02</radius>
            </cylinder>
          </geometry>
          <surface>
            <contact>
              <ode/>
            </contact>
            <friction>
              <ode/>
              <torsional>
                <ode/>
              </torsional>
            </friction>
            <bounce/>
          </surface>
          <max_contacts>10</max_contacts>
        </collision>
        <visual name='left_caster_rotation_link_visual'>
          <pose frame=''>0 0 0 0 -0 0</pose>
          <geometry>
            <cylinder>
              <length>0.03</length>
              <radius>0.02</radius>
            </cylinder>
          </geometry>
          <material>
            <script>
              <name>Gazebo/Red</name>
              <uri>file://media/materials/scripts/gazebo.material</uri>
            </script>
          </material>
        </visual>
        <gravity>1</gravity>
        <velocity_decay/>
        <self_collide>0</self_collide>
        <enable_wind>0</enable_wind>
        <kinematic>0</kinematic>
      </link>
      <joint name='left_caster_rotation_joint' type='revolute'>
        <child>left_caster_rotation_link</child>
        <parent>rotate_axis_link</parent>
        <axis>
          <xyz>0 0 1</xyz>
          <limit>
            <lower>-1e+16</lower>
            <upper>1e+16</upper>
          </limit>
          <dynamics>
            <damping>1</damping>
            <friction>1</friction>
            <spring_reference>0</spring_reference>
            <spring_stiffness>0</spring_stiffness>
          </dynamics>
          <use_parent_model_frame>1</use_parent_model_frame>
        </axis>
      </joint>
      <link name='left_caster_wheel_link'>
        <pose frame=''>0 0.25 0.111 0 -0 0</pose>
        <inertial>
          <pose frame=''>0 0 0 0 -0 0</pose>
          <mass>0.05</mass>
          <inertia>
            <ixx>2.83073e-05</ixx>
            <ixy>0</ixy>
            <ixz>0</ixz>
            <iyy>2.83073e-05</iyy>
            <iyz>0</iyz>
            <izz>5.64062e-05</izz>
          </inertia>
        </inertial>
        <collision name='left_caster_wheel_link_collision'>
          <pose frame=''>0 0 0 1.5708 -0 0</pose>
          <geometry>
            <cylinder>
              <length>0.005</length>
              <radius>0.0475</radius>
            </cylinder>
          </geometry>
          <surface>
            <contact>
              <ode>
                <kp>1e+06</kp>
                <kd>1</kd>
              </ode>
            </contact>
            <friction>
              <ode/>
              <torsional>
                <ode/>
              </torsional>
            </friction>
            <bounce/>
          </surface>
          <max_contacts>10</max_contacts>
        </collision>
        <visual name='left_caster_wheel_link_visual'>
          <pose frame=''>0 0 0 1.5708 -0 0</pose>
          <geometry>
            <cylinder>
              <length>0.005</length>
              <radius>0.0475</radius>
            </cylinder>
          </geometry>
          <material>
            <script>
              <uri>__default__</uri>
              <name>__default__</name>
            </script>
          </material>
        </visual>
        <gravity>1</gravity>
        <velocity_decay/>
        <gravity>1</gravity>
        <self_collide>0</self_collide>
        <enable_wind>0</enable_wind>
        <kinematic>0</kinematic>
      </link>
      <joint name='left_caster_wheel_joint' type='revolute'>
        <child>left_caster_wheel_link</child>
        <parent>left_caster_rotation_link</parent>
        <axis>
          <xyz>0 1 0</xyz>
          <limit>
            <lower>-1e+16</lower>
            <upper>1e+16</upper>
          </limit>
          <dynamics>
            <damping>1</damping>
            <friction>1</friction>
            <spring_reference>0</spring_reference>
            <spring_stiffness>0</spring_stiffness>
          </dynamics>
          <use_parent_model_frame>1</use_parent_model_frame>
        </axis>
      </joint>
      <link name='right_caster_rotation_link'>
        <pose frame=''>0 -0.25 0.181 0 -0 0</pose>
        <inertial>
          <pose frame=''>0 0 0.07 0 -0 0</pose>
          <mass>0.05</mass>
          <inertia>
            <ixx>0.000563333</ixx>
            <ixy>0</ixy>
            <ixz>0</ixz>
            <iyy>0.000563333</iyy>
            <iyz>0</iyz>
            <izz>0.000563333</izz>
          </inertia>
        </inertial>
        <collision name='right_caster_rotation_link_collision'>
          <pose frame=''>0 0 0 0 -0 0</pose>
          <geometry>
            <cylinder>
              <length>0.03</length>
              <radius>0.02</radius>
            </cylinder>
          </geometry>
          <surface>
            <contact>
              <ode/>
            </contact>
            <friction>
              <ode/>
              <torsional>
                <ode/>
              </torsional>
            </friction>
            <bounce/>
          </surface>
          <max_contacts>10</max_contacts>
        </collision>
        <visual name='right_caster_rotation_link_visual'>
          <pose frame=''>0 0 0 0 -0 0</pose>
          <geometry>
            <cylinder>
              <length>0.03</length>
              <radius>0.02</radius>
            </cylinder>
          </geometry>
          <material>
            <script>
              <name>Gazebo/Red</name>
              <uri>file://media/materials/scripts/gazebo.material</uri>
            </script>
          </material>
        </visual>
        <gravity>1</gravity>
        <velocity_decay/>
        <self_collide>0</self_collide>
        <enable_wind>0</enable_wind>
        <kinematic>0</kinematic>
      </link>
      <joint name='right_caster_rotation_joint' type='revolute'>
        <child>right_caster_rotation_link</child>
        <parent>rotate_axis_link</parent>
        <axis>
          <xyz>0 0 1</xyz>
          <limit>
            <lower>-1e+16</lower>
            <upper>1e+16</upper>
          </limit>
          <dynamics>
            <damping>1</damping>
            <friction>1</friction>
            <spring_reference>0</spring_reference>
            <spring_stiffness>0</spring_stiffness>
          </dynamics>
          <use_parent_model_frame>1</use_parent_model_frame>
        </axis>
      </joint>
      <link name='right_caster_wheel_link'>
        <pose frame=''>0 -0.25 0.111 0 -0 0</pose>
        <inertial>
          <pose frame=''>0 0 0 0 -0 0</pose>
          <mass>0.05</mass>
          <inertia>
            <ixx>2.83073e-05</ixx>
            <ixy>0</ixy>
            <ixz>0</ixz>
            <iyy>2.83073e-05</iyy>
            <iyz>0</iyz>
            <izz>5.64062e-05</izz>
          </inertia>
        </inertial>
        <collision name='right_caster_wheel_link_collision'>
          <pose frame=''>0 0 0 1.5708 -0 0</pose>
          <geometry>
            <cylinder>
              <length>0.005</length>
              <radius>0.0475</radius>
            </cylinder>
          </geometry>
          <surface>
            <contact>
              <ode>
                <kp>1e+06</kp>
                <kd>1</kd>
              </ode>
            </contact>
            <friction>
              <ode/>
              <torsional>
                <ode/>
              </torsional>
            </friction>
            <bounce/>
          </surface>
          <max_contacts>10</max_contacts>
        </collision>
        <visual name='right_caster_wheel_link_visual'>
          <pose frame=''>0 0 0 1.5708 -0 0</pose>
          <geometry>
            <cylinder>
              <length>0.005</length>
              <radius>0.0475</radius>
            </cylinder>
          </geometry>
          <material>
            <script>
              <uri>__default__</uri>
              <name>__default__</name>
            </script>
          </material>
        </visual>
        <gravity>1</gravity>
        <velocity_decay/>
        <gravity>1</gravity>
        <self_collide>0</self_collide>
        <enable_wind>0</enable_wind>
        <kinematic>0</kinematic>
      </link>
      <joint name='right_caster_wheel_joint' type='revolute'>
        <child>right_caster_wheel_link</child>
        <parent>right_caster_rotation_link</parent>
        <axis>
          <xyz>0 1 0</xyz>
          <limit>
            <lower>-1e+16</lower>
            <upper>1e+16</upper>
          </limit>
          <dynamics>
            <damping>1</damping>
            <friction>1</friction>
            <spring_reference>0</spring_reference>
            <spring_stiffness>0</spring_stiffness>
          </dynamics>
          <use_parent_model_frame>1</use_parent_model_frame>
        </axis>
      </joint>
      <link name='arm_shoulder_link'>
        <pose frame=''>-0 -0.620159 1.29 1.5708 0.785398 -0</pose>
        <inertial>
          <pose frame=''>0 0 0 0 -0 0</pose>
          <mass>0.00037</mass>
          <inertia>
            <ixx>1.02675e-06</ixx>
            <ixy>0</ixy>
            <ixz>0</ixz>
            <iyy>1.02675e-06</iyy>
            <iyz>0</iyz>
            <izz>6.66e-07</izz>
          </inertia>
        </inertial>
        <collision name='arm_shoulder_link_collision'>
          <pose frame=''>0 0 0 0 -0 0</pose>
          <geometry>
            <mesh>
              <scale>1 1 1</scale>
              <uri>/home/jiang/ppr_ws/src/gt_sim/gt_description/meshes/gtrobot_arm/collision/shoulder.stl</uri>
            </mesh>
          </geometry>
          <surface>
            <contact>
              <ode/>
            </contact>
            <friction>
              <ode/>
              <torsional>
                <ode/>
              </torsional>
            </friction>
            <bounce/>
          </surface>
          <max_contacts>10</max_contacts>
        </collision>
        <visual name='arm_shoulder_link_visual'>
          <pose frame=''>0 0 0 0 -0 0</pose>
          <geometry>
            <mesh>
              <scale>1 1 1</scale>
              <uri>/home/jiang/ppr_ws/src/gt_sim/gt_description/meshes/gtrobot_arm/visual/shoulder.dae</uri>
            </mesh>
          </geometry>
          <material>
            <script>
              <uri>__default__</uri>
              <name>__default__</name>
            </script>
          </material>
        </visual>
        <gravity>1</gravity>
        <velocity_decay/>
        <self_collide>1</self_collide>
        <enable_wind>0</enable_wind>
        <kinematic>0</kinematic>
      </link>
      <joint name='arm_shoulder_pan_joint' type='revolute'>
        <child>arm_shoulder_link</child>
        <parent>rotate_axis_link</parent>
        <axis>
          <xyz>-0 -1 -0</xyz>
          <limit>
            <lower>-6.28319</lower>
            <upper>6.28319</upper>
            <effort>150</effort>
            <velocity>3.15</velocity>
          </limit>
          <dynamics>
            <damping>0</damping>
            <friction>0</friction>
            <spring_reference>0</spring_reference>
            <spring_stiffness>0</spring_stiffness>
          </dynamics>
          <use_parent_model_frame>1</use_parent_model_frame>
        </axis>
      </joint>
      <link name='arm_upper_arm_link'>
        <pose frame=''>0.096061 -0.620159 1.38606 2.35619 -0 1.5708</pose>
        <inertial>
          <pose frame=''>0 0 0.28 0 -0 0</pose>
          <mass>0.0008393</mass>
          <inertia>
            <ixx>2.26891e-05</ixx>
            <ixy>0</ixy>
            <ixz>0</ixz>
            <iyy>2.26891e-05</iyy>
            <iyz>0</iyz>
            <izz>1.51074e-06</izz>
          </inertia>
        </inertial>
        <collision name='arm_upper_arm_link_collision'>
          <pose frame=''>0 0 0 0 -0 0</pose>
          <geometry>
            <mesh>
              <scale>1 1 1</scale>
              <uri>/home/jiang/ppr_ws/src/gt_sim/gt_description/meshes/gtrobot_arm/collision/upperarm.stl</uri>
            </mesh>
          </geometry>
          <surface>
            <contact>
              <ode/>
            </contact>
            <friction>
              <ode/>
              <torsional>
                <ode/>
              </torsional>
            </friction>
            <bounce/>
          </surface>
          <max_contacts>10</max_contacts>
        </collision>
        <visual name='arm_upper_arm_link_visual'>
          <pose frame=''>0 0 0 0 -0 0</pose>
          <geometry>
            <mesh>
              <scale>1 1 1</scale>
              <uri>/home/jiang/ppr_ws/src/gt_sim/gt_description/meshes/gtrobot_arm/visual/upperarm.dae</uri>
            </mesh>
          </geometry>
          <material>
            <script>
              <uri>__default__</uri>
              <name>__default__</name>
            </script>
          </material>
        </visual>
        <gravity>1</gravity>
        <velocity_decay/>
        <self_collide>1</self_collide>
        <enable_wind>0</enable_wind>
        <kinematic>0</kinematic>
      </link>
      <joint name='arm_shoulder_lift_joint' type='revolute'>
        <child>arm_upper_arm_link</child>
        <parent>arm_shoulder_link</parent>
        <axis>
          <xyz>0.707107 -0 0.707107</xyz>
          <limit>
            <lower>-6.28319</lower>
            <upper>6.28319</upper>
            <effort>150</effort>
            <velocity>3.15</velocity>
          </limit>
          <dynamics>
            <damping>0</damping>
            <friction>0</friction>
            <spring_reference>0</spring_reference>
            <spring_stiffness>0</spring_stiffness>
          </dynamics>
          <use_parent_model_frame>1</use_parent_model_frame>
        </axis>
      </joint>
      <link name='arm_forearm_link'>
        <pose frame=''>0.31194 -0.620159 1.0009 2.35619 -0 1.5708</pose>
        <inertial>
          <pose frame=''>0 0 0.196125 0 -0 0</pose>
          <mass>2.275e-05</mass>
          <inertia>
            <ixx>3.12168e-07</ixx>
            <ixy>0</ixy>
            <ixz>0</ixz>
            <iyy>3.12168e-07</iyy>
            <iyz>0</iyz>
            <izz>4.095e-08</izz>
          </inertia>
        </inertial>
        <collision name='arm_forearm_link_collision'>
          <pose frame=''>0 0 0 0 -0 0</pose>
          <geometry>
            <mesh>
              <scale>1 1 1</scale>
              <uri>/home/jiang/ppr_ws/src/gt_sim/gt_description/meshes/gtrobot_arm/collision/forearm.stl</uri>
            </mesh>
          </geometry>
          <surface>
            <contact>
              <ode/>
            </contact>
            <friction>
              <ode/>
              <torsional>
                <ode/>
              </torsional>
            </friction>
            <bounce/>
          </surface>
          <max_contacts>10</max_contacts>
        </collision>
        <visual name='arm_forearm_link_visual'>
          <pose frame=''>0 0 0 0 -0 0</pose>
          <geometry>
            <mesh>
              <scale>1 1 1</scale>
              <uri>/home/jiang/ppr_ws/src/gt_sim/gt_description/meshes/gtrobot_arm/visual/forearm.dae</uri>
            </mesh>
          </geometry>
          <material>
            <script>
              <uri>__default__</uri>
              <name>__default__</name>
            </script>
          </material>
        </visual>
        <gravity>1</gravity>
        <velocity_decay/>
        <self_collide>1</self_collide>
        <enable_wind>0</enable_wind>
        <kinematic>0</kinematic>
      </link>
      <joint name='arm_elbow_joint' type='revolute'>
        <child>arm_forearm_link</child>
        <parent>arm_upper_arm_link</parent>
        <axis>
          <xyz>0.707107 -0 0.707107</xyz>
          <limit>
            <lower>-3.14159</lower>
            <upper>3.14159</upper>
            <effort>150</effort>
            <velocity>3.15</velocity>
          </limit>
          <dynamics>
            <damping>0</damping>
            <friction>0</friction>
            <spring_reference>0</spring_reference>
            <spring_stiffness>0</spring_stiffness>
          </dynamics>
          <use_parent_model_frame>1</use_parent_model_frame>
        </axis>
      </joint>
      <link name='arm_wrist_1_link'>
        <pose frame=''>0.589303 -0.620159 0.723537 1.5708 -0.785398 3.14159</pose>
        <inertial>
          <pose frame=''>0 0.093 0 0 -0 0</pose>
          <mass>1.219e-05</mass>
          <inertia>
            <ixx>2.5599e-08</ixx>
            <ixy>0</ixy>
            <ixz>0</ixz>
            <iyy>2.5599e-08</iyy>
            <iyz>0</iyz>
            <izz>2.1942e-08</izz>
          </inertia>
        </inertial>
        <collision name='arm_wrist_1_link_collision'>
          <pose frame=''>0 0 0 0 -0 0</pose>
          <geometry>
            <mesh>
              <scale>1 1 1</scale>
              <uri>/home/jiang/ppr_ws/src/gt_sim/gt_description/meshes/gtrobot_arm/collision/wrist1.stl</uri>
            </mesh>
          </geometry>
          <surface>
            <contact>
              <ode/>
            </contact>
            <friction>
              <ode/>
              <torsional>
                <ode/>
              </torsional>
            </friction>
            <bounce/>
          </surface>
          <max_contacts>10</max_contacts>
        </collision>
        <visual name='arm_wrist_1_link_visual'>
          <pose frame=''>0 0 0 0 -0 0</pose>
          <geometry>
            <mesh>
              <scale>1 1 1</scale>
              <uri>/home/jiang/ppr_ws/src/gt_sim/gt_description/meshes/gtrobot_arm/visual/wrist1.dae</uri>
            </mesh>
          </geometry>
          <material>
            <script>
              <uri>__default__</uri>
              <name>__default__</name>
            </script>
          </material>
        </visual>
        <gravity>1</gravity>
        <velocity_decay/>
        <self_collide>1</self_collide>
        <enable_wind>0</enable_wind>
        <kinematic>0</kinematic>
      </link>
      <joint name='arm_wrist_1_joint' type='revolute'>
        <child>arm_wrist_1_link</child>
        <parent>arm_forearm_link</parent>
        <axis>
          <xyz>0.707107 -0 0.707107</xyz>
          <limit>
            <lower>-6.28319</lower>
            <upper>6.28319</upper>
            <effort>28</effort>
            <velocity>3.2</velocity>
          </limit>
          <dynamics>
            <damping>0</damping>
            <friction>0</friction>
            <spring_reference>0</spring_reference>
            <spring_stiffness>0</spring_stiffness>
          </dynamics>
          <use_parent_model_frame>1</use_parent_model_frame>
        </axis>
      </joint>
      <link name='arm_wrist_2_link'>
        <pose frame=''>0.655064 -0.620159 0.789298 1.5708 -0.785398 3.14159</pose>
        <inertial>
          <pose frame=''>0 0 0.09465 0 -0 0</pose>
          <mass>1.219e-05</mass>
          <inertia>
            <ixx>2.5599e-08</ixx>
            <ixy>0</ixy>
            <ixz>0</ixz>
            <iyy>2.5599e-08</iyy>
            <iyz>0</iyz>
            <izz>2.1942e-08</izz>
          </inertia>
        </inertial>
        <collision name='arm_wrist_2_link_collision'>
          <pose frame=''>0 0 0 0 -0 0</pose>
          <geometry>
            <mesh>
              <scale>1 1 1</scale>
              <uri>/home/jiang/ppr_ws/src/gt_sim/gt_description/meshes/gtrobot_arm/collision/wrist2.stl</uri>
            </mesh>
          </geometry>
          <surface>
            <contact>
              <ode/>
            </contact>
            <friction>
              <ode/>
              <torsional>
                <ode/>
              </torsional>
            </friction>
            <bounce/>
          </surface>
          <max_contacts>10</max_contacts>
        </collision>
        <visual name='arm_wrist_2_link_visual'>
          <pose frame=''>0 0 0 0 -0 0</pose>
          <geometry>
            <mesh>
              <scale>1 1 1</scale>
              <uri>/home/jiang/ppr_ws/src/gt_sim/gt_description/meshes/gtrobot_arm/visual/wrist2.dae</uri>
            </mesh>
          </geometry>
          <material>
            <script>
              <uri>__default__</uri>
              <name>__default__</name>
            </script>
          </material>
        </visual>
        <gravity>1</gravity>
        <velocity_decay/>
        <self_collide>1</self_collide>
        <enable_wind>0</enable_wind>
        <kinematic>0</kinematic>
      </link>
      <joint name='arm_wrist_2_joint' type='revolute'>
        <child>arm_wrist_2_link</child>
        <parent>arm_wrist_1_link</parent>
        <axis>
          <xyz>0 1 -0</xyz>
          <limit>
            <lower>-6.28319</lower>
            <upper>6.28319</upper>
            <effort>28</effort>
            <velocity>3.2</velocity>
          </limit>
          <dynamics>
            <damping>0</damping>
            <friction>0</friction>
            <spring_reference>0</spring_reference>
            <spring_stiffness>0</spring_stiffness>
          </dynamics>
          <use_parent_model_frame>1</use_parent_model_frame>
        </axis>
      </joint>
      <link name='arm_wrist_3_link'>
        <pose frame=''>0.655064 -0.525509 0.789298 1.5708 -0.785398 3.14159</pose>
        <inertial>
          <pose frame=''>0 0.06505 0 1.5708 -0 0</pose>
          <mass>1.879e-06</mass>
          <inertia>
            <ixx>8.46959e-10</ixx>
            <ixy>0</ixy>
            <ixz>0</ixz>
            <iyy>8.46959e-10</iyy>
            <iyz>0</iyz>
            <izz>1.32117e-09</izz>
          </inertia>
        </inertial>
        <collision name='arm_wrist_3_link_collision'>
          <pose frame=''>0 0 0 0 -0 0</pose>
          <geometry>
            <mesh>
              <scale>1 1 1</scale>
              <uri>/home/jiang/ppr_ws/src/gt_sim/gt_description/meshes/gtrobot_arm/collision/wrist3.stl</uri>
            </mesh>
          </geometry>
          <surface>
            <contact>
              <ode/>
            </contact>
            <friction>
              <ode/>
              <torsional>
                <ode/>
              </torsional>
            </friction>
            <bounce/>
          </surface>
          <max_contacts>10</max_contacts>
        </collision>
        <collision name='arm_wrist_3_link_fixed_joint_lump__arm_ee_link_collision_1'>
          <pose frame=''>-0 0.0723 0 0 -0 1.5708</pose>
          <geometry>
            <box>
              <size>0.01 0.01 0.01</size>
            </box>
          </geometry>
          <surface>
            <contact>
              <ode/>
            </contact>
            <friction>
              <ode/>
              <torsional>
                <ode/>
              </torsional>
            </friction>
            <bounce/>
          </surface>
          <max_contacts>10</max_contacts>
        </collision>
        <visual name='arm_wrist_3_link_visual'>
          <pose frame=''>0 0 0 0 -0 0</pose>
          <geometry>
            <mesh>
              <scale>1 1 1</scale>
              <uri>/home/jiang/ppr_ws/src/gt_sim/gt_description/meshes/gtrobot_arm/visual/wrist3.dae</uri>
            </mesh>
          </geometry>
          <material>
            <script>
              <uri>__default__</uri>
              <name>__default__</name>
            </script>
          </material>
        </visual>
        <velocity_decay/>
        <gravity>1</gravity>
        <velocity_decay/>
        <self_collide>1</self_collide>
        <enable_wind>0</enable_wind>
        <kinematic>0</kinematic>
      </link>
      <joint name='arm_wrist_3_joint' type='revolute'>
        <child>arm_wrist_3_link</child>
        <parent>arm_wrist_2_link</parent>
        <axis>
          <xyz>0.707107 -0 0.707107</xyz>
          <limit>
            <lower>-6.28319</lower>
            <upper>6.28319</upper>
            <effort>28</effort>
            <velocity>3.2</velocity>
          </limit>
          <dynamics>
            <damping>0</damping>
            <friction>0</friction>
            <spring_reference>0</spring_reference>
            <spring_stiffness>0</spring_stiffness>
          </dynamics>
          <use_parent_model_frame>1</use_parent_model_frame>
        </axis>
      </joint>

      <!-- parabot -->
      <include>
        <uri>model://ppr_description/sdf/parabot.sdf</uri>
        <pose>5 0 1 0 0 0</pose>
        <name>parabot</name>
      </include>
      <!-- <joint name="parabot_base_fixed" type="fixed">
        <parent>arm_wrist_3_link</parent>
        <child>parabot::lower_platform</child>
      </joint> -->

      <plugin name='ros_control' filename='libgazebo_ros_control.so'>
        <robotSimType>gazebo_ros_control/DefaultRobotHWSim</robotSimType>
        <legacyModeNS>1</legacyModeNS>
        <robotNamespace>/</robotNamespace>
      </plugin>
      <static>0</static>
      <plugin name='p3d_base_controller' filename='libgazebo_ros_p3d.so'>
        <alwaysOn>1</alwaysOn>
        <updateRate>50.0</updateRate>
        <bodyName>stereo_l_stereo_camera_optical_frame</bodyName>
        <topicName>gazebo_ground_truth</topicName>
        <gaussianNoise>0.0</gaussianNoise>
        <frameName>world</frameName>
        <xyzOffsets>0 0 0</xyzOffsets>
        <rpyOffsets>0 0 0</rpyOffsets>
        <robotNamespace>/</robotNamespace>
      </plugin>
      <pose frame=''>0 0 0 0 -0 0</pose>
    </model>
    <!-- <model name="parabot">
      <link name="base_link"/>
      <include>
        <uri>model://ppr_description/sdf/parabot.sdf</uri>
        <pose>0 0 0 0 0 0</pose>
        <name>parabot_model</name>
        <joint name='j1' type='fixed'>
          <parent>base_link</parent>
          <child>parabot_model::lower_platform</child>
        </joint>
      </include>
    </model> -->
    <state world_name='default'>
      <sim_time>44 221000000</sim_time>
      <real_time>45 144194162</real_time>
      <wall_time>1600156329 409155106</wall_time>
      <iterations>44221</iterations>
      <model name='ground_plane'>
        <pose frame=''>0 0 0 0 -0 0</pose>
        <scale>1 1 1</scale>
        <link name='link'>
          <pose frame=''>0 0 0 0 -0 0</pose>
          <velocity>0 0 0 0 -0 0</velocity>
          <acceleration>0 0 0 0 -0 0</acceleration>
          <wrench>0 0 0 0 -0 0</wrench>
        </link>
      </model>
      <model name='xianquzhe'>
        <pose frame=''>3.2e-05 -0.000424 -0.063576 0 -0 -3e-06</pose>
        <scale>1 1 1</scale>
        <link name='arm_forearm_link'>
          <pose frame=''>0.31278 -0.62055 0.938254 2.35331 -7.9e-05 1.57088</pose>
          <velocity>0.004942 -8e-06 0.001621 0.000139 -0.016026 -9.4e-05</velocity>
          <acceleration>-0 0 -0 2e-06 -0 3e-06</acceleration>
          <wrench>-0 0 -0 0 -0 0</wrench>
        </link>
        <link name='arm_shoulder_link'>
          <pose frame=''>2.9e-05 -0.620583 1.22645 1.5708 0.782311 -3e-06</pose>
          <velocity>1.2e-05 -4e-06 -0.003175 5e-06 -0.009813 -5e-06</velocity>
          <acceleration>-0 0 -0 1e-06 -0 0</acceleration>
          <wrench>-0 0 -0 0 -0 0</wrench>
        </link>
        <link name='arm_upper_arm_link'>
          <pose frame=''>0.095795 -0.620584 1.32279 2.35331 -5.7e-05 1.57085</pose>
          <velocity>-0.001109 -6e-06 -0.001786 -4.5e-05 -0.015948 -3.2e-05</velocity>
          <acceleration>0 -0 -0 7e-06 -0 -6e-06</acceleration>
          <wrench>0 -0 -0 0 -0 0</wrench>
        </link>
        <link name='arm_wrist_1_link'>
          <pose frame=''>0.590943 -0.620507 0.661687 1.57045 -0.782508 -3.14111</pose>
          <velocity>0.00915 0.000131 0.006265 0.0004 -0.015108 0.000656</velocity>
          <acceleration>-0 0 -0 2e-06 0 -2e-06</acceleration>
          <wrench>-0 0 -0 0 -0 0</wrench>
        </link>
        <link name='arm_wrist_2_link'>
          <pose frame=''>0.656516 -0.620507 0.727635 1.57047 -0.782623 -3.14113</pose>
          <velocity>0.007951 0.000148 0.00728 0.000475 -0.0148 0.001757</velocity>
          <acceleration>0 0 -0 5e-06 0 -2e-06</acceleration>
          <wrench>0 0 -0 0 -0 0</wrench>
        </link>
        <link name='arm_wrist_3_link'>
          <pose frame=''>0.656495 -0.525857 0.727653 1.57046 -0.782605 -3.14112</pose>
          <velocity>0.007603 0.000143 0.007522 0.000424 -0.01391 0.001804</velocity>
          <acceleration>0 0 -0 1e-05 -0 -1e-05</acceleration>
          <wrench>0 0 -0 0 -0 0</wrench>
        </link>
        <link name='base_footprint'>
          <pose frame=''>3.2e-05 -0.000424 -0.063576 0 -0 -3e-06</pose>
          <velocity>-0 -8e-06 -0.001237 2e-06 2e-06 0</velocity>
          <acceleration>0 0 0 0 -0 0</acceleration>
          <wrench>0 0 0 0 -0 0</wrench>
        </link>
        <link name='bl_caster_rotation_link'>
          <pose frame=''>-0.259967 0.512577 0.117466 -0 -0 -3e-06</pose>
          <velocity>-3e-06 -1.5e-05 -0.004291 -4.4e-05 -1e-06 -0</velocity>
          <acceleration>0 0 0 0 -0 0</acceleration>
          <wrench>0 0 0 0 -0 0</wrench>
        </link>
        <link name='bl_caster_wheel_link'>
          <pose frame=''>-0.259967 0.512577 0.047479 -3.1e-05 0.000379 -3e-06</pose>
          <velocity>-3e-06 -4.6e-05 -0.00501 0.000965 -5.7e-05 0</velocity>
          <acceleration>0 0 0 0 -0 3e-05</acceleration>
          <wrench>0 0 0 0 -0 0</wrench>
        </link>
        <link name='br_caster_rotation_link'>
          <pose frame=''>-0.25997 -0.513423 0.117466 0 -0 1e-06</pose>
          <velocity>-5e-06 -1.9e-05 -0.004299 -3.3e-05 1e-06 0</velocity>
          <acceleration>0 -0 -0 0 -0 0</acceleration>
          <wrench>0 -0 -0 0 -0 0</wrench>
        </link>
        <link name='br_caster_wheel_link'>
          <pose frame=''>-0.25997 -0.513423 0.047479 -3.1e-05 0.000394 1e-06</pose>
          <velocity>-5e-06 -4.8e-05 -0.005024 0.001019 -0.000106 0</velocity>
          <acceleration>0 -0 0 0 -0 5.8e-05</acceleration>
          <wrench>0 -0 0 0 -0 0</wrench>
        </link>
        <link name='fl_caster_rotation_link'>
          <pose frame=''>0.260033 0.512575 0.117466 0 -0 5e-06</pose>
          <velocity>-3e-06 -1.5e-05 -0.004293 -4.4e-05 9e-06 -0</velocity>
          <acceleration>0 0 0 0 -0 0</acceleration>
          <wrench>0 0 0 0 -0 0</wrench>
        </link>
        <link name='fl_caster_wheel_link'>
          <pose frame=''>0.260033 0.512576 0.047479 -3.1e-05 0.000385 5e-06</pose>
          <velocity>-3e-06 -4.6e-05 -0.005014 0.000971 -6.6e-05 0</velocity>
          <acceleration>0 0 -0 0 -0 4.1e-05</acceleration>
          <wrench>0 0 -0 0 -0 0</wrench>
        </link>
        <link name='fr_caster_rotation_link'>
          <pose frame=''>0.26003 -0.513425 0.117466 0 -0 1e-06</pose>
          <velocity>-1e-06 -1.9e-05 -0.004301 -3.4e-05 7e-06 0</velocity>
          <acceleration>0 0 -0 0 -0 0</acceleration>
          <wrench>0 0 -0 0 -0 0</wrench>
        </link>
        <link name='fr_caster_wheel_link'>
          <pose frame=''>0.26003 -0.513424 0.047479 -3.1e-05 0.000371 1e-06</pose>
          <velocity>-1e-06 -4.9e-05 -0.005028 0.001025 -2.1e-05 0</velocity>
          <acceleration>0 0 -0 0 -0 1.5e-05</acceleration>
          <wrench>0 0 -0 0 -0 0</wrench>
        </link>
        <link name='left_caster_rotation_link'>
          <pose frame=''>3.2e-05 0.249576 0.117466 -0 -0 -3e-06</pose>
          <velocity>-1e-06 -1.7e-05 -0.004306 -4.3e-05 2e-06 -0</velocity>
          <acceleration>0 0 0 0 -0 0</acceleration>
          <wrench>0 0 0 0 -0 0</wrench>
        </link>
        <link name='left_caster_wheel_link'>
          <pose frame=''>3.2e-05 0.249577 0.047479 -3.1e-05 0.000368 -3e-06</pose>
          <velocity>-1e-06 -4.8e-05 -0.005042 0.001018 -1.6e-05 -0</velocity>
          <acceleration>0 0 -0 0 -0 1e-05</acceleration>
          <wrench>0 0 -0 0 -0 0</wrench>
        </link>
        <link name='right_caster_rotation_link'>
          <pose frame=''>3.1e-05 -0.250424 0.117466 -0 -0 -3e-06</pose>
          <velocity>-1e-06 -1.9e-05 -0.004312 -3.8e-05 2e-06 0</velocity>
          <acceleration>0 0 -0 0 -0 0</acceleration>
          <wrench>0 0 -0 0 -0 0</wrench>
        </link>
        <link name='right_caster_wheel_link'>
          <pose frame=''>3.1e-05 -0.250423 0.047479 -3.2e-05 0.000369 -3e-06</pose>
          <velocity>-1e-06 -5e-05 -0.005054 0.001049 -1.6e-05 0</velocity>
          <acceleration>0 0 -0 0 -0 1e-05</acceleration>
          <wrench>0 0 -0 0 -0 0</wrench>
        </link>
        <link name='rotate_axis_link'>
          <pose frame=''>3.2e-05 -0.000424 -0.032554 0 -0 -3e-06</pose>
          <velocity>-2e-06 -5e-06 -0.003172 -1e-06 5e-06 0</velocity>
          <acceleration>-0 -0 -0 0 -0 0</acceleration>
          <wrench>-0 -0 -0 0 -0 0</wrench>
        </link>
        <link name='x_axis_link'>
          <pose frame=''>3.2e-05 -0.000424 -0.052581 0 -0 -3e-06</pose>
          <velocity>-0 -7e-06 -0.000817 3e-06 1e-06 -0</velocity>
          <acceleration>0 0 0 0 -0 0</acceleration>
          <wrench>0 0 0 0 -0 0</wrench>
        </link>
        <link name='y_axis_link'>
          <pose frame=''>3.2e-05 -0.000424 -0.04257 0 -0 -3e-06</pose>
          <velocity>-1e-06 -0 -0.001778 1e-06 2e-06 0</velocity>
          <acceleration>-0 0 -0 0 -0 0</acceleration>
          <wrench>-0 0 -0 0 -0 0</wrench>
        </link>
      </model>
      <light name='sun'>
        <pose frame=''>0 0 10 0 -0 0</pose>
      </light>
    </state>
    <gui fullscreen='0'>
      <camera name='user_camera'>
        <pose frame=''>3.45564 -2.07542 1.74453 0 0.361795 2.7482</pose>
        <view_controller>orbit</view_controller>
        <projection_type>perspective</projection_type>
      </camera>
    </gui>
  </world>
</sdf>
