<?xml version='1.0'?>
<sdf version='1.6'>
  <model name='parabot'>
    <link name='lower_platform'>
      <pose frame=''>0 0 0 0 -0 0</pose>
      <inertial>
        <pose frame=''>-8e-06 -0 0.000606 0 -0 0</pose>
        <mass>0.0603778</mass>
        <inertia>
          <ixx>5.44707e-05</ixx>
          <ixy>-3.39473e-13</ixy>
          <ixz>-3.70667e-09</ixz>
          <iyy>5.44893e-05</iyy>
          <iyz>8.47232e-14</iyz>
          <izz>0.00010778</izz>
        </inertia>
      </inertial>
      <collision name='lower_platform_collision'>
        <pose frame=''>0 0 0 0 -0 0</pose>
        <inertial>
          <pose frame=''>-8e-06 -0 0.000606 0 -0 0</pose>
          <mass>0.0603778</mass>
          <inertia>
            <ixx>5.44707e-05</ixx>
            <ixy>-3.39473e-13</ixy>
            <ixz>-3.70667e-09</ixz>
            <iyy>5.44893e-05</iyy>
            <iyz>8.47232e-14</iyz>
            <izz>0.00010778</izz>
          </inertia>
        </inertial>
        <collision name='lower_platform_collision'>
          <pose frame=''>0 0 0 0 -0 0</pose>
          <geometry>
            <mesh>
              <scale>1 1 1</scale>
              <uri>/home/jason/catkin_ws/src/ppr_stack/ppr_description/meshes/lower_platform.STL</uri>
            </mesh>
          </geometry>
          <max_contacts>10</max_contacts>
        </collision>
        <visual name='lower_platform_visual'>
          <pose frame=''>0 0 0 0 0 0</pose>
          <geometry>
            <mesh>
              <scale>1 1 1</scale>
              <uri>/home/jason/catkin_ws/src/ppr_stack/ppr_description/meshes/lower_platform.STL</uri>
            </mesh>
          </geometry>
          <material>
                    <script>
                        <name>Gazebo/Orange</name>
                    </script>
                </material>
        </visual>
        <self_collide>0</self_collide>
        <enable_wind>0</enable_wind>
        <kinematic>0</kinematic>
      </link>
       <joint name="fixed_para" type="fixed">
            <pose>0 0 0.5 0 0 0</pose>
            <parent>world</parent>
            <child>lower_platform</child>
        </joint>

      <link name='motor1_link'>
        <pose frame=''>-0.06 -0.0001 0 0 -0 0</pose>
        <inertial>
          <pose frame=''>-0.003328 -4.5e-05 0.035558 0 -0 0</pose>
           <mass>0.0174008</mass>
          <inertia>
            <ixx>2.10767e-06</ixx>
            <ixy>3.14927e-09</ixy>
            <ixz>8.63406e-08</ixz>
            <iyy>2.42005e-06</iyy>
            <iyz>9.17533e-09</iyz>
            <izz>1.25993e-06</izz>
          </inertia>
        </inertial>
        <collision name='motor1_collision'>
          <pose frame=''>0 0 0 0 0 0</pose>
          <geometry>
            <mesh>
              <scale>1 1 1</scale>
              <uri>/home/jason/catkin_ws/src/ppr_stack/ppr_description/meshes/motor1.STL</uri>
            </mesh>
          </geometry>
          <max_contacts>10</max_contacts>
        </collision>
        <visual name='motor1_visual'>
          <pose frame=''>0 0 0 0 -0 0</pose>
          <geometry>
            <mesh>
              <scale>1 1 1</scale>
              <uri>/home/jason/catkin_ws/src/ppr_stack/ppr_description/meshes/motor1.STL</uri>
            </mesh>
          </geometry>
          <material>
                    <script>
                        <name>Gazebo/Black</name>
                    </script>
                </material>
        </visual>
        <self_collide>0</self_collide>
        <enable_wind>0</enable_wind>
        <kinematic>0</kinematic>
      </link>
      <joint name='motor1_joint' type='revolute'>
        <child>motor1_link</child>
        <parent>lower_platform</parent>
        <axis>
          <xyz>0 1 0</xyz>
          <limit>
            <lower>-0.785</lower>
            <upper>0.785</upper>
            <effort>100</effort>
            <velocity>10</velocity>
          </limit>
          <dynamics>
            <spring_reference>0</spring_reference>
            <spring_stiffness>0</spring_stiffness>
          </dynamics>
          <use_parent_model_frame>1</use_parent_model_frame>
        </axis>
      </joint>
      <link name='connection1'>
        <pose frame=''>-0.06 -0.0001 0.0734 0 0 -0.017453</pose>
        <inertial>
          <pose frame=''>-0 -0 0.004082 0 -0 0</pose>
          <mass>0.0028116</mass>
          <inertia>
            <ixx>5.98751e-07</ixx>
            <ixy>-6.59627e-13</ixy>
            <ixz>1.8379e-12</ixz>
            <iyy>5.98749e-07</iyy>
            <iyz>6.08145e-13</iyz>
            <izz>3.55554e-08</izz>
          </inertia>
        </inertial>
        <collision name='connection1_collision'>
          <pose frame=''>0 0 0 0 -0 0</pose>
          <geometry>
            <mesh>
              <scale>1 1 1</scale>
              <uri>/home/jason/catkin_ws/src/ppr_stack/ppr_description/meshes/connection1.STL</uri>
            </mesh>
          </geometry>
          <max_contacts>10</max_contacts>
        </collision>
        <visual name='connection1_visual'>
          <pose frame=''>0 0 0 0 -0 0</pose>
          <geometry>
            <mesh>
              <scale>1 1 1</scale>
              <uri>/home/jason/catkin_ws/src/ppr_stack/ppr_description/meshes/connection1.STL</uri>
            </mesh>
          </geometry>
        </visual>
        <self_collide>0</self_collide>
        <enable_wind>0</enable_wind>
        <kinematic>0</kinematic>
      </link>
      <joint name='motor1' type='prismatic'>
        <child>connection1</child>
        <parent>motor1_link</parent>
        <axis>
          <xyz>0 0 1</xyz>
          <limit>
            <lower>0.0</lower>
            <upper>0.027</upper>
            <effort>100</effort>
            <velocity>10</velocity>
          </limit>
          <dynamics>
            <damping>0.7</damping>
          </dynamics>
          <use_parent_model_frame>1</use_parent_model_frame>
        </axis>
      </joint>
      <link name='motor2_link'>
        <pose frame=''>0.030087 -0.051912 0 0 -0 2.0944</pose>
        <inertial>
          <pose frame=''>-0.003328 -4.5e-05 0.035558 0 -0 0</pose>
          <mass>0.0174009</mass>
          <inertia>
            <ixx>2.10767e-06</ixx>
            <ixy>3.15004e-09</ixy>
            <ixz>8.63405e-08</ixz>
            <iyy>2.42005e-06</iyy>
            <iyz>9.17523e-09</iyz>
            <izz>1.25993e-06</izz>
          </inertia>
        </inertial>
        <collision name='motor2_collision'>
          <pose frame=''>0 0 0 0 -0 0</pose>
          <geometry>
            <mesh>
              <scale>1 1 1</scale>
              <uri>/home/jason/catkin_ws/src/ppr_stack/ppr_description/meshes/motor2.STL</uri>
            </mesh>
          </geometry>
          <max_contacts>10</max_contacts>
        </collision>
        <visual name='motor2_visual'>
          <pose frame=''>0 0 0 0 -0 0</pose>
          <geometry>
            <mesh>
              <scale>1 1 1</scale>
              <uri>/home/jason/catkin_ws/src/ppr_stack/ppr_description/meshes/motor2.STL</uri>
            </mesh>
          </geometry>
          <material>
                    <script>
                        <name>Gazebo/Black</name>
                    </script>
                </material>
        </visual>
        <self_collide>0</self_collide>
        <enable_wind>0</enable_wind>
        <kinematic>0</kinematic>
      </link>
      <joint name='motor2_joint' type='revolute'>
        <child>motor2_link</child>
        <parent>lower_platform</parent>
        <axis>
          <xyz>-0.866025 -0.5 0</xyz>
          <limit>
            <lower>-0.785</lower>
            <upper>0.785</upper>
            <effort>100</effort>
            <velocity>10</velocity>
          </limit>
          <dynamics>
            <spring_reference>0</spring_reference>
            <spring_stiffness>0</spring_stiffness>
          </dynamics>
          <use_parent_model_frame>1</use_parent_model_frame>
        </axis>
      </joint>
      <link name='connection2'>
        <pose frame=''>0.030087 -0.051912 0.0734 0 -0 2.07694</pose>
        <inertial>
          <pose frame=''>-0 -0 0.004082 0 -0 0</pose>
          <mass>0.0028116</mass>
          <inertia>
            <ixx>5.98751e-07</ixx>
            <ixy>-6.77924e-13</ixy>
            <ixz>1.83316e-12</ixz>
            <iyy>5.98748e-07</iyy>
            <iyz>6.19296e-13</iyz>
            <izz>3.55554e-08</izz>
          </inertia>
        </inertial>
        <collision name='connection2_collision'>
          <pose frame=''>0 0 0 0 -0 0</pose>
          <geometry>
            <mesh>
              <scale>1 1 1</scale>
              <uri>/home/jason/catkin_ws/src/ppr_stack/ppr_description/meshes/connection2.STL</uri>
            </mesh>
          </geometry>
          <max_contacts>10</max_contacts>
        </collision>
        <visual name='connection2_visual'>
          <pose frame=''>0 0 0 0 -0 0</pose>
          <geometry>
            <mesh>
              <scale>1 1 1</scale>
              <uri>/home/jason/catkin_ws/src/ppr_stack/ppr_description/meshes/connection2.STL</uri>
            </mesh>
          </geometry>
        </visual>
        <self_collide>0</self_collide>
        <enable_wind>0</enable_wind>
        <kinematic>0</kinematic>
      </link>
      <joint name='motor2' type='prismatic'>
        <child>connection2</child>
        <parent>motor2_link</parent>
        <axis>
          <xyz>0 0 1</xyz>
          <limit>
            <lower>0.0</lower>
            <upper>0.027</upper>
            <effort>100</effort>
            <velocity>10</velocity>
          </limit>
          <dynamics>
            <damping>0.7</damping>
          </dynamics>
          <use_parent_model_frame>1</use_parent_model_frame>
        </axis>
      </joint>
      <link name='motor3_link'>
        <pose frame=''>0.029913 0.052012 0 0 0 -2.0944</pose>
        <inertial>
          <pose frame=''>-0.003328 -4.5e-05 0.035558 0 -0 0</pose>
          <mass>0.0174008</mass>
          <inertia>
            <ixx>2.10767e-06</ixx>
            <ixy>3.14947e-09</ixy>
            <ixz>8.63405e-08</ixz>
            <iyy>2.42005e-06</iyy>
            <iyz>9.17555e-09</iyz>
            <izz>1.25993e-06</izz>
          </inertia>
        </inertial>
        <collision name='motor3_collision'>
          <pose frame=''>0 0 0 0 -0 0</pose>
          <geometry>
            <mesh>
              <scale>1 1 1</scale>
              <uri>/home/jason/catkin_ws/src/ppr_stack/ppr_description/meshes/motor3.STL</uri>
            </mesh>
          </geometry>
          <max_contacts>10</max_contacts>
        </collision>
        <visual name='motor3_visual'>
          <pose frame=''>0 0 0 0 -0 0</pose>
          <geometry>
            <mesh>
              <scale>1 1 1</scale>
              <uri>/home/jason/catkin_ws/src/ppr_stack/ppr_description/meshes/motor3.STL</uri>
            </mesh>
          </geometry>
          <material>
                    <script>
                        <name>Gazebo/Black</name>
                    </script>
                </material>
        </visual>
        <self_collide>0</self_collide>
        <enable_wind>0</enable_wind>
        <kinematic>0</kinematic>
      </link>
      <joint name='motor3_joint' type='revolute'>
        <child>motor3_link</child>
        <parent>lower_platform</parent>
        <axis>
          <xyz>0.866025 -0.5 0</xyz>
          <limit>
            <lower>-0.785</lower>
            <upper>0.785</upper>
            <effort>100</effort>
            <velocity>10</velocity>
          </limit>
          <dynamics>
            <spring_reference>0</spring_reference>
            <spring_stiffness>0</spring_stiffness>
          </dynamics>
          <use_parent_model_frame>1</use_parent_model_frame>
        </axis>
      </joint>
      <link name='connection3'>
        <pose frame=''>0.029913 0.052012 0.0734 0 0 -2.11185</pose>
        <inertial>
          <pose frame=''>-0 -0 0.004082 0 -0 0</pose>
          <mass>0.0028116</mass>
          <inertia>
            <ixx>5.98751e-07</ixx>
            <ixy>-6.73669e-13</ixy>
            <ixz>1.74604e-12</ixz>
            <iyy>5.98748e-07</iyy>
            <iyz>5.9774e-13</iyz>
            <izz>3.55554e-08</izz>
          </inertia>
        </inertial>
        <collision name='connection3_collision'>
          <pose frame=''>0 0 0 0 -0 0</pose>
          <geometry>
            <mesh>
              <scale>1 1 1</scale>
              <uri>/home/jason/catkin_ws/src/ppr_stack/ppr_description/meshes/connection3.STL</uri>
            </mesh>
          </geometry>
          <max_contacts>10</max_contacts>
        </collision>
        <visual name='connection3_visual'>
          <pose frame=''>0 0 0 0 -0 0</pose>
          <geometry>
            <mesh>
              <scale>1 1 1</scale>
              <uri>/home/jason/catkin_ws/src/ppr_stack/ppr_description/meshes/connection3.STL</uri>
            </mesh>
          </geometry>
        </visual>
        <self_collide>0</self_collide>
        <enable_wind>0</enable_wind>
        <kinematic>0</kinematic>
      </link>
      <joint name='motor3' type='prismatic'>
        <child>connection3</child>
        <parent>motor3_link</parent>
        <axis>
          <xyz>0 0 1</xyz>
          <limit>
            <lower>0.0</lower>
            <upper>0.027</upper>
            <effort>100</effort>
            <velocity>10</velocity>
          </limit>
          <dynamics>
            <damping>0.7</damping>
          </dynamics>
          <use_parent_model_frame>1</use_parent_model_frame>
        </axis>
      </joint>

     
      <link name='upper_platform3'>
        <pose frame=''>-0 -0 0.1049ray 0 -0 0</pose>
        <inertial>
          <pose frame=''>0 -0 -0.031799 0 -0 0</pose>
          <mass>0.30122</mass>
          <inertia>
            <ixx>0.00120425</ixx>
            <ixy>2.31001e-09</ixy>
            <ixz>6.44215e-11</ixz>
            <iyy>0.00120406</iyy>
            <iyz>-3.65634e-11</iyz>
            <izz>0.00211065</izz>
          </inertia>
        </inertial>
        <collision name='upper_platform3_collision'>
          <pose frame=''>0 0 0 0 -0 0</pose>
          <geometry>
            <mesh>
              <scale>1 1 1</scale>
              <uri>/home/jason/catkin_ws/src/ppr_stack/ppr_description/meshes/upper_platform3.STL</uri>
            </mesh>
          </geometry>
          <max_contacts>10</max_contacts>
        </collision>
        <visual name='upper_platform3_visual'>
          <pose frame=''>0 0 0 0 0 0</pose>
          <geometry>
            <mesh>
              <scale>1 1 1</scale>
              <uri>/home/jason/catkin_ws/src/ppr_stack/ppr_description/meshes/upper_platform3.STL</uri>
            </mesh>
          </geometry>
          <material>
                    <script>
                        <name>Gazebo/Orange</name>
                    </script>
                </material>
        </visual>

    <link name='upper_platform'>
      <pose frame=''>-0 -0 0.135513ray 0 -0 0</pose>
      <inertial>
        <pose frame=''>1.5e-05 -8e-06 -0.031799 0 -0 0</pose>
        <mass>0.30122</mass>
        <inertia>
          <ixx>0.000239611231064541</ixx>
          <ixy>-3.70810221178748e-14</ixy>
          <ixz>-1.01144890837118e-14</ixz>
          <iyy>0.00023945415085988</iyy>
          <iyz>1.44059471768371e-14</iyz>
          <izz>0.000359706115663781</izz>
        </inertia>
      </inertial>
      <collision name='upper_platform_collision'>
        <pose frame=''>0 0 0 0 -0 0</pose>
        <geometry>
          <mesh>
            <scale>1 1 1</scale>
            <uri>model://ppr_description/meshes/upper_platform3.STL</uri>
          </mesh>
        </geometry>
        <max_contacts>10</max_contacts>
      </collision>
      <visual name='upper_platform_visual'>
        <pose frame=''>0 0 0 0 0 0</pose>
        <geometry>
          <mesh>
            <scale>1 1 1</scale>
            <uri>model://ppr_description/meshes/upper_platform3.STL</uri>
          </mesh>
        </geometry>
        <material>
          <script>
            <name>Gazebo/Orange</name>
          </script>
        </material>
      </visual>

<<<<<<< HEAD
      <!-- laser sensor 1 -->
      <collision name='upper_platform_fixed_joint_lump__sensor1_collision_1'>
        <pose frame=''>0 0 0.113013 0 0 -3.14159</pose>
        <geometry>
          <mesh>
            <scale>1 1 1</scale>
            <uri>model://ppr_description/meshes/sensor1.STL</uri>
          </mesh>
        </geometry>
        <max_contacts>10</max_contacts>
      </collision>
      <visual name='upper_platform_fixed_joint_lump__sensor1_visual_1'>
        <pose frame=''>-0.1175 0 -0.014373 0 0 -3.14159</pose>
        <geometry>
          <mesh>
            <scale>1 1 1</scale>
            <uri>model://ppr_description/meshes/sensor1.STL</uri>
          </mesh>
        </geometry>
        <material>
          <script>
            <name>Gazebo/Blue</name>
          </script>
        </material>
      </visual>

      <sensor name="laser1" type="ray">
        <pose>-0.1175 0 -0.014373 0 -1.570796327 0</pose>
        <visualize>true</visualize>
        <update_rate>125</update_rate>
        <ray>
          <scan>
            <horizontal>
              <samples>1</samples>
              <resolution>1</resolution>
              <min_angle>-0.000</min_angle>
              <max_angle>0.000</max_angle>
            </horizontal>
          </scan>
          <range>
            <min>0.10</min>
            <max>1.0</max>
            <resolution>0.01</resolution>
          </range>
          <noise>
            <type>gaussian</type>
            <mean>0.0</mean>
            <stddev>0.0001</stddev>
          </noise>
        </ray>
        <plugin name="gazebo_ros_laser_controller1" filename="libgazebo_ros_laser.so">
          <topicName>parabot/laser1</topicName>
          <frameName>upper_platform</frameName>
        </plugin>
      </sensor>

      <!-- laser sensor 2 -->
      <collision name='upper_platform_fixed_joint_lump__sensor2_collision_2'>
        <pose frame=''>0 0 0.113013 0 0 -1.0472</pose>
        <geometry>
          <mesh>
            <scale>1 1 1</scale>
            <uri>model://ppr_description/meshes/sensor2.STL</uri>
          </mesh>
        </geometry>
        <max_contacts>10</max_contacts>
      </collision>
      <visual name='upper_platform_fixed_joint_lump__sensor2_visual_2'>
        <pose frame=''>0.05875 -0.101758 -0.014373 0 0 -1.0472</pose>
        <geometry>
          <mesh>
            <scale>1 1 1</scale>
            <uri>model://ppr_description/meshes/sensor2.STL</uri>
          </mesh>
        </geometry>
        <material>
          <script>
            <name>Gazebo/Blue</name>
          </script>
        </material>
      </visual>

      <sensor name="laser2" type="ray">
        <pose>0.05875 -0.101758 -0.014373 0 -1.570796327 0</pose>
        <visualize>true</visualize>
        <update_rate>125</update_rate>
        <ray>
          <scan>
            <horizontal>
              <samples>1</samples>
              <resolution>1</resolution>
              <min_angle>-0.000</min_angle>
              <max_angle>0.000</max_angle>
            </horizontal>
          </scan>
          <range>
            <min>0.10</min>
            <max>1.0</max>
            <resolution>0.01</resolution>
          </range>
          <noise>
            <type>gaussian</type>
            <mean>0.0</mean>
            <stddev>0.0001</stddev>
          </noise>
        </ray>
        <plugin name="gazebo_ros_laser_controller2" filename="libgazebo_ros_laser.so">
          <topicName>parabot/laser2</topicName>
          <frameName>upper_platform</frameName>
        </plugin>
      </sensor>

      <!-- laser sensor 3 -->
      <collision name='upper_platform_fixed_joint_lump__sensor3_collision_3'>
        <pose frame=''>0 0 0.113013 0 -0 1.0472</pose>
        <geometry>
          <mesh>
            <scale>1 1 1</scale>
            <uri>model://ppr_description/meshes/sensor3.STL</uri>
          </mesh>
        </geometry>
        <max_contacts>10</max_contacts>
      </collision>
      <visual name='upper_platform_fixed_joint_lump__sensor3_visual_3'>
        <pose frame=''>0.05875 0.101758 -0.014373 0 -0 1.0472</pose>
        <geometry>
          <mesh>
            <scale>1 1 1</scale>
            <uri>model://ppr_description/meshes/sensor3.STL</uri>
          </mesh>
        </geometry>
        <material>
          <script>
            <name>Gazebo/Blue</name>
          </script>
        </material>
      </visual>

      <sensor name="laser3" type="ray">
        <pose>0.05875 0.101758 -0.014373 0 -1.570796327 0</pose>
        <visualize>true</visualize>
        <update_rate>125</update_rate>
        <ray>
          <scan>
            <horizontal>
              <samples>1</samples>
              <resolution>1</resolution>
              <min_angle>-0.000</min_angle>
              <max_angle>0.000</max_angle>
            </horizontal>
          </scan>
          <range>
            <min>0.10</min>
            <max>1.0</max>
            <resolution>0.01</resolution>
          </range>
          <noise>
            <type>gaussian</type>
            <mean>0.0</mean>
            <stddev>0.0001</stddev>
          </noise>
        </ray>
        <plugin name="gazebo_ros_laser_controller3" filename="libgazebo_ros_laser.so">
          <topicName>parabot/laser3</topicName>
          <frameName>upper_platform</frameName>
        </plugin>
      </sensor>
=======
 
        <collision name='upper_platform3_fixed_joint_lump__sensor1_collision_1'>
          <pose frame=''>0 0 -0.0225 0 0 -3.14159</pose>
          <geometry>
            <mesh>
              <scale>1 1 1</scale>
              <uri>/home/jason/catkin_ws/src/ppr_stack/ppr_description/meshes/sensor1.STL</uri>
            </mesh>
          </geometry>
          <max_contacts>10</max_contacts>
        </collision>
        <visual name='upper_platform3_fixed_joint_lump__sensor1_visual_1'>
          <pose frame=''>-0.1175 0 -0.0225 0 0 -3.14159</pose>
          <geometry>
            <mesh>
              <scale>1 1 1</scale>
              <uri>/home/jason/catkin_ws/src/ppr_stack/ppr_description/meshes/sensor1.STL</uri>
            </mesh>
          </geometry>
          <material>
                    <script>
                        <name>Gazebo/Red</name>
                    </script>
                </material>
        </visual>

             <sensor name="laser1" type="ray">
                <pose>-0.1175 0 -0.0225 0 -1.570796327 0</pose>
                <visualize>true</visualize>
                <update_rate>125</update_rate>
                <ray>
                    <scan>
                        <horizontal>
                            <samples>1</samples>
                            <resolution>1</resolution>
                            <min_angle>-0.000</min_angle>
                            <max_angle>0.000</max_angle>
                        </horizontal>
                    </scan>
                    <range>
                        <min>0.10</min>
                        <max>1.0</max>
                        <resolution>0.01</resolution>
                    </range>
                    <noise>
                        <type>gaussian</type>
                        <mean>0.0</mean>
                        <stddev>0.0001</stddev>
                    </noise>
                </ray>
                <plugin name="gazebo_ros_laser_controller1" filename="libgazebo_ros_laser.so">
                    <topicName>parabot/laser1</topicName>
                    <frameName>upper_platform3</frameName>
                </plugin>
            </sensor>

        <collision name='upper_platform3_fixed_joint_lump__sensor2_collision_2'>
           <pose frame=''>0 0 -0.0225 0 0 -1.0472</pose>
          <geometry>
            <mesh>
              <scale>1 1 1</scale>
              <uri>/home/jason/catkin_ws/src/ppr_stack/ppr_description/meshes/sensor2.STL</uri>
            </mesh>
          </geometry>
          <max_contacts>10</max_contacts>
        </collision>
             <visual name='upper_platform3_fixed_joint_lump__sensor2_visual_2'>
          <pose frame=''>0.05875 -0.101758 -0.0225 0 0 -1.0472</pose>
          <geometry>
            <mesh>
              <scale>1 1 1</scale>
              <uri>/home/jason/catkin_ws/src/ppr_stack/ppr_description/meshes/sensor2.STL</uri>
            </mesh>
          </geometry>
          <material>
                    <script>
                        <name>Gazebo/Blue</name>
                    </script>
                </material>
        </visual>

                <sensor name="laser2" type="ray">
                <pose>0.05875 -0.101758 -0.0225 0 -1.570796327 0</pose>
                <visualize>true</visualize>
                <update_rate>125</update_rate>
                <ray>
                    <scan>
                        <horizontal>
                            <samples>1</samples>
                            <resolution>1</resolution>
                            <min_angle>-0.000</min_angle>
                            <max_angle>0.000</max_angle>
                        </horizontal>
                    </scan>
                    <range>
                        <min>0.10</min>
                        <max>1.0</max>
                        <resolution>0.01</resolution>
                    </range>
                    <noise>
                        <type>gaussian</type>
                        <mean>0.0</mean>
                        <stddev>0.0001</stddev>
                    </noise>
                </ray>
                <plugin name="gazebo_ros_laser_controller2" filename="libgazebo_ros_laser.so">
                    <topicName>parabot/laser2</topicName>
                    <frameName>upper_platform3</frameName>
                </plugin>
         </sensor>

        <collision name='upper_platform3_fixed_joint_lump__sensor3_collision_3'>
          <pose frame=''>0 0 -0.0225 0 -0 1.0472</pose>
          <geometry>
            <mesh>
              <scale>1 1 1</scale>
              <uri>/home/jason/catkin_ws/src/ppr_stack/ppr_description/meshes/sensor3.STL</uri>
            </mesh>
          </geometry>
          <max_contacts>10</max_contacts>
        </collision>
         <visual name='upper_platform3_fixed_joint_lump__sensor3_visual_3'>
          <pose frame=''>0.05875 0.101758 -0.0225 0 -0 1.0472</pose>
          <geometry>
            <mesh>
              <scale>1 1 1</scale>
              <uri>/home/jason/catkin_ws/src/ppr_stack/ppr_description/meshes/sensor3.STL</uri>
            </mesh>
          </geometry>
          <material>
                    <script>
                        <name>Gazebo/Green</name>
                    </script>
                </material>
        </visual>

                 <sensor name="laser3" type="ray">
                <pose>0.05875 0.101758 -0.0225 0 -1.570796327 0</pose>
                <visualize>true</visualize>
                <update_rate>125</update_rate>
                <ray>
                    <scan>
                        <horizontal>
                            <samples>1</samples>
                            <resolution>1</resolution>
                            <min_angle>-0.000</min_angle>
                            <max_angle>0.000</max_angle>
                        </horizontal>
                    </scan>
                    <range>
                        <min>0.10</min>
                        <max>1.0</max>
                        <resolution>0.01</resolution>
                    </range>
                    <noise>
                        <type>gaussian</type>
                        <mean>0.0</mean>
                        <stddev>0.0001</stddev>
                    </noise>
                </ray>
                <plugin name="gazebo_ros_laser_controller3" filename="libgazebo_ros_laser.so">
                    <topicName>parabot/laser3</topicName>
                    <frameName>upper_platform3</frameName>
                </plugin>
         </sensor>
>>>>>>> 717500a7ecd015c4b789994ab685f3d65dce2667

    </link>

    <joint name='ball3' type='ball'>
      <pose>0.029913 0.052012 -0.007 0 0 0 </pose>
      <child>upper_platform</child>
      <parent>connection3</parent>
    </joint>

    <joint name='ball1' type='ball'>
      <pose>-0.06 -0.0001 -0.007 0 0 0</pose>
      <child>upper_platform</child>
      <parent>connection1</parent>
    </joint>

    <joint name='ball2' type='ball'>
      <pose>0.030087 -0.051912 -0.007 0 0 0</pose>
      <child>upper_platform</child>
      <parent>connection2</parent>
    </joint>

    <plugin name="parabot_hw_sim_plugin" filename="libparabot_plugin.so">
      <robotNamespace>parabot</robotNamespace>
      <jointName>poineer/parabot/motor1 poineer/parabot/motor2 poineer/parabot/motor3</jointName>
    </plugin>

  </model>

</sdf>